[36m[2020-01-13 11:20:00 DEBUG] [cli:70][39m ###############################################################################
[36m[2020-01-13 11:20:00 DEBUG] [cli:71][39m Running command 'init'
[36m[2020-01-13 11:20:00 DEBUG] [cli:75][39m Using settings file '/Users/john/.chaostoolkit/settings.yaml'
[36m[2020-01-13 11:20:00 DEBUG] [settings:24][39m The Chaos Toolkit settings file could not be found at '/Users/john/.chaostoolkit/settings.yaml'.
[36m[2020-01-13 11:25:24 DEBUG] [cli:70][39m ###############################################################################
[36m[2020-01-13 11:25:24 DEBUG] [cli:71][39m Running command 'run'
[36m[2020-01-13 11:25:24 DEBUG] [cli:75][39m Using settings file '/Users/john/.chaostoolkit/settings.yaml'
[36m[2020-01-13 11:25:29 DEBUG] [cli:70][39m ###############################################################################
[36m[2020-01-13 11:25:29 DEBUG] [cli:71][39m Running command 'run'
[36m[2020-01-13 11:25:29 DEBUG] [cli:75][39m Using settings file '/Users/john/.chaostoolkit/settings.yaml'
[36m[2020-01-13 11:25:29 DEBUG] [settings:24][39m The Chaos Toolkit settings file could not be found at '/Users/john/.chaostoolkit/settings.yaml'.
[36m[2020-01-13 11:25:29 DEBUG] [__init__:355][39m No controls to apply on 'loader'
[36m[2020-01-13 11:25:29 DEBUG] [__init__:355][39m No controls to apply on 'loader'
[36m[2020-01-13 11:25:29 DEBUG] [caching:25][39m Building activity cache...
[36m[2020-01-13 11:25:29 DEBUG] [caching:35][39m Cached 1 activities
[32m[2020-01-13 11:25:29 INFO] [experiment:54][39m Validating the experiment's syntax
[36m[2020-01-13 11:25:29 DEBUG] [configuration:36][39m Loading configuration...
[36m[2020-01-13 11:25:29 DEBUG] [secret:74][39m Loading secrets...
[36m[2020-01-13 11:25:29 DEBUG] [secret:89][39m Secrets loaded
[36m[2020-01-13 11:25:29 DEBUG] [caching:42][39m Clearing activities cache
[31m[2020-01-13 11:25:29 ERROR] [cli:119][39m an experiment requires a method with at least one activity
[36m[2020-01-13 11:25:29 DEBUG] [cli:120][39m an experiment requires a method with at least one activity
[36m[2020-01-13 11:28:30 DEBUG] [cli:70][39m ###############################################################################
[36m[2020-01-13 11:28:30 DEBUG] [cli:71][39m Running command 'run'
[36m[2020-01-13 11:28:30 DEBUG] [cli:75][39m Using settings file '/Users/john/.chaostoolkit/settings.yaml'
[36m[2020-01-13 11:28:30 DEBUG] [settings:24][39m The Chaos Toolkit settings file could not be found at '/Users/john/.chaostoolkit/settings.yaml'.
[36m[2020-01-13 11:28:30 DEBUG] [__init__:355][39m No controls to apply on 'loader'
[36m[2020-01-13 11:28:30 DEBUG] [__init__:355][39m No controls to apply on 'loader'
[36m[2020-01-13 11:28:30 DEBUG] [caching:25][39m Building activity cache...
[36m[2020-01-13 11:28:30 DEBUG] [caching:35][39m Cached 2 activities
[32m[2020-01-13 11:28:30 INFO] [experiment:54][39m Validating the experiment's syntax
[36m[2020-01-13 11:28:30 DEBUG] [configuration:36][39m Loading configuration...
[36m[2020-01-13 11:28:30 DEBUG] [secret:74][39m Loading secrets...
[36m[2020-01-13 11:28:30 DEBUG] [secret:89][39m Secrets loaded
[32m[2020-01-13 11:28:30 INFO] [experiment:100][39m Experiment looks valid
[36m[2020-01-13 11:28:30 DEBUG] [caching:42][39m Clearing activities cache
[36m[2020-01-13 11:28:30 DEBUG] [caching:25][39m Building activity cache...
[36m[2020-01-13 11:28:30 DEBUG] [caching:35][39m Cached 2 activities
[32m[2020-01-13 11:28:30 INFO] [experiment:179][39m Running experiment: Delay Movie Recommendation
[36m[2020-01-13 11:28:30 DEBUG] [configuration:36][39m Loading configuration...
[36m[2020-01-13 11:28:30 DEBUG] [secret:74][39m Loading secrets...
[36m[2020-01-13 11:28:30 DEBUG] [secret:89][39m Secrets loaded
[36m[2020-01-13 11:28:30 DEBUG] [__init__:39][39m Initializing controls
[36m[2020-01-13 11:28:30 DEBUG] [__init__:355][39m No controls to apply on 'experiment'
[32m[2020-01-13 11:28:30 INFO] [hypothesis:184][39m Steady state hypothesis: Movie recommendation in less than a second
[36m[2020-01-13 11:28:30 DEBUG] [__init__:355][39m No controls to apply on 'hypothesis'
[36m[2020-01-13 11:28:30 DEBUG] [__init__:355][39m No controls to apply on 'activity'
[32m[2020-01-13 11:28:30 INFO] [activity:158][39m Probe: we-can-request-sunset
[36m[2020-01-13 11:28:30 DEBUG] [activity:230][39m Activity failed
    Traceback (most recent call last):
      File "/Users/john/.venvs/chaostk/lib/python3.7/site-packages/urllib3/connectionpool.py", line 672, in urlopen
        chunked=chunked,
      File "/Users/john/.venvs/chaostk/lib/python3.7/site-packages/urllib3/connectionpool.py", line 376, in _make_request
        self._validate_conn(conn)
      File "/Users/john/.venvs/chaostk/lib/python3.7/site-packages/urllib3/connectionpool.py", line 994, in _validate_conn
        conn.connect()
      File "/Users/john/.venvs/chaostk/lib/python3.7/site-packages/urllib3/connection.py", line 394, in connect
        ssl_context=context,
      File "/Users/john/.venvs/chaostk/lib/python3.7/site-packages/urllib3/util/ssl_.py", line 370, in ssl_wrap_socket
        return context.wrap_socket(sock, server_hostname=server_hostname)
      File "/usr/local/Cellar/python/3.7.5/Frameworks/Python.framework/Versions/3.7/lib/python3.7/ssl.py", line 423, in wrap_socket
        session=session
      File "/usr/local/Cellar/python/3.7.5/Frameworks/Python.framework/Versions/3.7/lib/python3.7/ssl.py", line 870, in _create
        self.do_handshake()
      File "/usr/local/Cellar/python/3.7.5/Frameworks/Python.framework/Versions/3.7/lib/python3.7/ssl.py", line 1139, in do_handshake
        self._sslobj.do_handshake()
    ssl.SSLError: [SSL: WRONG_VERSION_NUMBER] wrong version number (_ssl.c:1076)
    
    During handling of the above exception, another exception occurred:
    
    Traceback (most recent call last):
      File "/Users/john/.venvs/chaostk/lib/python3.7/site-packages/requests/adapters.py", line 449, in send
        timeout=timeout
      File "/Users/john/.venvs/chaostk/lib/python3.7/site-packages/urllib3/connectionpool.py", line 720, in urlopen
        method, url, error=e, _pool=self, _stacktrace=sys.exc_info()[2]
      File "/Users/john/.venvs/chaostk/lib/python3.7/site-packages/urllib3/util/retry.py", line 436, in increment
        raise MaxRetryError(_pool, url, error or ResponseError(cause))
    urllib3.exceptions.MaxRetryError: HTTPSConnectionPool(host='localhost', port=8080): Max retries exceeded with url: /movies (Caused by SSLError(SSLError(1, '[SSL: WRONG_VERSION_NUMBER] wrong version number (_ssl.c:1076)')))
    
    During handling of the above exception, another exception occurred:
    
    Traceback (most recent call last):
      File "/Users/john/.venvs/chaostk/lib/python3.7/site-packages/chaoslib/provider/http.py", line 53, in run_http_activity
        verify=verify_tls)
      File "/Users/john/.venvs/chaostk/lib/python3.7/site-packages/requests/sessions.py", line 546, in get
        return self.request('GET', url, **kwargs)
      File "/Users/john/.venvs/chaostk/lib/python3.7/site-packages/requests/sessions.py", line 533, in request
        resp = self.send(prep, **send_kwargs)
      File "/Users/john/.venvs/chaostk/lib/python3.7/site-packages/requests/sessions.py", line 646, in send
        r = adapter.send(request, **kwargs)
      File "/Users/john/.venvs/chaostk/lib/python3.7/site-packages/requests/adapters.py", line 514, in send
        raise SSLError(e, request=request)
    requests.exceptions.SSLError: HTTPSConnectionPool(host='localhost', port=8080): Max retries exceeded with url: /movies (Caused by SSLError(SSLError(1, '[SSL: WRONG_VERSION_NUMBER] wrong version number (_ssl.c:1076)')))
    
    During handling of the above exception, another exception occurred:
    
    Traceback (most recent call last):
      File "/Users/john/.venvs/chaostk/lib/python3.7/site-packages/chaoslib/activity.py", line 227, in run_activity
        result = run_http_activity(activity, configuration, secrets)
      File "/Users/john/.venvs/chaostk/lib/python3.7/site-packages/chaoslib/provider/http.py", line 87, in run_http_activity
        u=url, x=str(cex)))
    chaoslib.exceptions.ActivityFailed: failed to connect to https://localhost:8080/movies: HTTPSConnectionPool(host='localhost', port=8080): Max retries exceeded with url: /movies (Caused by SSLError(SSLError(1, '[SSL: WRONG_VERSION_NUMBER] wrong version number (_ssl.c:1076)')))
[31m[2020-01-13 11:28:30 ERROR] [activity:184][39m   => failed: failed to connect to https://localhost:8080/movies: HTTPSConnectionPool(host='localhost', port=8080): Max retries exceeded with url: /movies (Caused by SSLError(SSLError(1, '[SSL: WRONG_VERSION_NUMBER] wrong version number (_ssl.c:1076)')))
[36m[2020-01-13 11:28:30 DEBUG] [__init__:355][39m No controls to apply on 'activity'
[33m[2020-01-13 11:28:30 WARNING] [hypothesis:201][39m Probe terminated unexpectedly, so its tolerance could not be validated
[36m[2020-01-13 11:28:30 DEBUG] [__init__:355][39m No controls to apply on 'hypothesis'
[2020-01-13 11:28:30 CRITICAL] [experiment:215] Steady state probe 'we-can-request-sunset' is not in the given tolerance so failing this experiment
[32m[2020-01-13 11:28:30 INFO] [experiment:320][39m Let's rollback...
[36m[2020-01-13 11:28:30 DEBUG] [__init__:355][39m No controls to apply on 'rollback'
[32m[2020-01-13 11:28:30 INFO] [rollback:25][39m No declared rollbacks, let's move on.
[36m[2020-01-13 11:28:30 DEBUG] [__init__:355][39m No controls to apply on 'rollback'
[32m[2020-01-13 11:28:30 INFO] [experiment:270][39m Experiment ended with status: failed
[36m[2020-01-13 11:28:30 DEBUG] [__init__:355][39m No controls to apply on 'experiment'
[36m[2020-01-13 11:28:30 DEBUG] [__init__:72][39m Cleaning up controls
[36m[2020-01-13 11:28:30 DEBUG] [caching:42][39m Clearing activities cache
[36m[2020-01-13 11:29:04 DEBUG] [cli:70][39m ###############################################################################
[36m[2020-01-13 11:29:04 DEBUG] [cli:71][39m Running command 'run'
[36m[2020-01-13 11:29:04 DEBUG] [cli:75][39m Using settings file '/Users/john/.chaostoolkit/settings.yaml'
[36m[2020-01-13 11:29:05 DEBUG] [settings:24][39m The Chaos Toolkit settings file could not be found at '/Users/john/.chaostoolkit/settings.yaml'.
[36m[2020-01-13 11:29:05 DEBUG] [__init__:355][39m No controls to apply on 'loader'
[36m[2020-01-13 11:29:05 DEBUG] [__init__:355][39m No controls to apply on 'loader'
[36m[2020-01-13 11:29:05 DEBUG] [caching:25][39m Building activity cache...
[36m[2020-01-13 11:29:05 DEBUG] [caching:35][39m Cached 2 activities
[32m[2020-01-13 11:29:05 INFO] [experiment:54][39m Validating the experiment's syntax
[36m[2020-01-13 11:29:05 DEBUG] [configuration:36][39m Loading configuration...
[36m[2020-01-13 11:29:05 DEBUG] [secret:74][39m Loading secrets...
[36m[2020-01-13 11:29:05 DEBUG] [secret:89][39m Secrets loaded
[32m[2020-01-13 11:29:05 INFO] [experiment:100][39m Experiment looks valid
[36m[2020-01-13 11:29:05 DEBUG] [caching:42][39m Clearing activities cache
[36m[2020-01-13 11:29:05 DEBUG] [caching:25][39m Building activity cache...
[36m[2020-01-13 11:29:05 DEBUG] [caching:35][39m Cached 2 activities
[32m[2020-01-13 11:29:05 INFO] [experiment:179][39m Running experiment: Delay Movie Recommendation
[36m[2020-01-13 11:29:05 DEBUG] [configuration:36][39m Loading configuration...
[36m[2020-01-13 11:29:05 DEBUG] [secret:74][39m Loading secrets...
[36m[2020-01-13 11:29:05 DEBUG] [secret:89][39m Secrets loaded
[36m[2020-01-13 11:29:05 DEBUG] [__init__:39][39m Initializing controls
[36m[2020-01-13 11:29:05 DEBUG] [__init__:355][39m No controls to apply on 'experiment'
[32m[2020-01-13 11:29:05 INFO] [hypothesis:184][39m Steady state hypothesis: Movie recommendation in less than a second
[36m[2020-01-13 11:29:05 DEBUG] [__init__:355][39m No controls to apply on 'hypothesis'
[36m[2020-01-13 11:29:05 DEBUG] [__init__:355][39m No controls to apply on 'activity'
[32m[2020-01-13 11:29:05 INFO] [activity:158][39m Probe: we-can-request-sunset
[36m[2020-01-13 11:29:06 DEBUG] [activity:230][39m Activity failed
    Traceback (most recent call last):
      File "/Users/john/.venvs/chaostk/lib/python3.7/site-packages/urllib3/connectionpool.py", line 421, in _make_request
        six.raise_from(e, None)
      File "<string>", line 3, in raise_from
      File "/Users/john/.venvs/chaostk/lib/python3.7/site-packages/urllib3/connectionpool.py", line 416, in _make_request
        httplib_response = conn.getresponse()
      File "/usr/local/Cellar/python/3.7.5/Frameworks/Python.framework/Versions/3.7/lib/python3.7/http/client.py", line 1344, in getresponse
        response.begin()
      File "/usr/local/Cellar/python/3.7.5/Frameworks/Python.framework/Versions/3.7/lib/python3.7/http/client.py", line 306, in begin
        version, status, reason = self._read_status()
      File "/usr/local/Cellar/python/3.7.5/Frameworks/Python.framework/Versions/3.7/lib/python3.7/http/client.py", line 267, in _read_status
        line = str(self.fp.readline(_MAXLINE + 1), "iso-8859-1")
      File "/usr/local/Cellar/python/3.7.5/Frameworks/Python.framework/Versions/3.7/lib/python3.7/socket.py", line 589, in readinto
        return self._sock.recv_into(b)
    socket.timeout: timed out
    
    During handling of the above exception, another exception occurred:
    
    Traceback (most recent call last):
      File "/Users/john/.venvs/chaostk/lib/python3.7/site-packages/requests/adapters.py", line 449, in send
        timeout=timeout
      File "/Users/john/.venvs/chaostk/lib/python3.7/site-packages/urllib3/connectionpool.py", line 720, in urlopen
        method, url, error=e, _pool=self, _stacktrace=sys.exc_info()[2]
      File "/Users/john/.venvs/chaostk/lib/python3.7/site-packages/urllib3/util/retry.py", line 400, in increment
        raise six.reraise(type(error), error, _stacktrace)
      File "/Users/john/.venvs/chaostk/lib/python3.7/site-packages/urllib3/packages/six.py", line 735, in reraise
        raise value
      File "/Users/john/.venvs/chaostk/lib/python3.7/site-packages/urllib3/connectionpool.py", line 672, in urlopen
        chunked=chunked,
      File "/Users/john/.venvs/chaostk/lib/python3.7/site-packages/urllib3/connectionpool.py", line 423, in _make_request
        self._raise_timeout(err=e, url=url, timeout_value=read_timeout)
      File "/Users/john/.venvs/chaostk/lib/python3.7/site-packages/urllib3/connectionpool.py", line 331, in _raise_timeout
        self, url, "Read timed out. (read timeout=%s)" % timeout_value
    urllib3.exceptions.ReadTimeoutError: HTTPConnectionPool(host='localhost', port=8080): Read timed out. (read timeout=1)
    
    During handling of the above exception, another exception occurred:
    
    Traceback (most recent call last):
      File "/Users/john/.venvs/chaostk/lib/python3.7/site-packages/chaoslib/provider/http.py", line 53, in run_http_activity
        verify=verify_tls)
      File "/Users/john/.venvs/chaostk/lib/python3.7/site-packages/requests/sessions.py", line 546, in get
        return self.request('GET', url, **kwargs)
      File "/Users/john/.venvs/chaostk/lib/python3.7/site-packages/requests/sessions.py", line 533, in request
        resp = self.send(prep, **send_kwargs)
      File "/Users/john/.venvs/chaostk/lib/python3.7/site-packages/requests/sessions.py", line 646, in send
        r = adapter.send(request, **kwargs)
      File "/Users/john/.venvs/chaostk/lib/python3.7/site-packages/requests/adapters.py", line 529, in send
        raise ReadTimeout(e, request=request)
    requests.exceptions.ReadTimeout: HTTPConnectionPool(host='localhost', port=8080): Read timed out. (read timeout=1)
    
    During handling of the above exception, another exception occurred:
    
    Traceback (most recent call last):
      File "/Users/john/.venvs/chaostk/lib/python3.7/site-packages/chaoslib/activity.py", line 227, in run_activity
        result = run_http_activity(activity, configuration, secrets)
      File "/Users/john/.venvs/chaostk/lib/python3.7/site-packages/chaoslib/provider/http.py", line 89, in run_http_activity
        raise ActivityFailed("activity took too long to complete")
    chaoslib.exceptions.ActivityFailed: activity took too long to complete
[31m[2020-01-13 11:29:06 ERROR] [activity:184][39m   => failed: activity took too long to complete
[36m[2020-01-13 11:29:06 DEBUG] [__init__:355][39m No controls to apply on 'activity'
[33m[2020-01-13 11:29:06 WARNING] [hypothesis:201][39m Probe terminated unexpectedly, so its tolerance could not be validated
[36m[2020-01-13 11:29:06 DEBUG] [__init__:355][39m No controls to apply on 'hypothesis'
[2020-01-13 11:29:06 CRITICAL] [experiment:215] Steady state probe 'we-can-request-sunset' is not in the given tolerance so failing this experiment
[32m[2020-01-13 11:29:06 INFO] [experiment:320][39m Let's rollback...
[36m[2020-01-13 11:29:06 DEBUG] [__init__:355][39m No controls to apply on 'rollback'
[32m[2020-01-13 11:29:06 INFO] [rollback:25][39m No declared rollbacks, let's move on.
[36m[2020-01-13 11:29:06 DEBUG] [__init__:355][39m No controls to apply on 'rollback'
[32m[2020-01-13 11:29:06 INFO] [experiment:270][39m Experiment ended with status: failed
[36m[2020-01-13 11:29:06 DEBUG] [__init__:355][39m No controls to apply on 'experiment'
[36m[2020-01-13 11:29:06 DEBUG] [__init__:72][39m Cleaning up controls
[36m[2020-01-13 11:29:06 DEBUG] [caching:42][39m Clearing activities cache
[36m[2020-01-13 11:29:22 DEBUG] [cli:70][39m ###############################################################################
[36m[2020-01-13 11:29:22 DEBUG] [cli:71][39m Running command 'run'
[36m[2020-01-13 11:29:22 DEBUG] [cli:75][39m Using settings file '/Users/john/.chaostoolkit/settings.yaml'
[36m[2020-01-13 11:29:23 DEBUG] [settings:24][39m The Chaos Toolkit settings file could not be found at '/Users/john/.chaostoolkit/settings.yaml'.
[36m[2020-01-13 11:29:23 DEBUG] [__init__:355][39m No controls to apply on 'loader'
[36m[2020-01-13 11:29:23 DEBUG] [__init__:355][39m No controls to apply on 'loader'
[36m[2020-01-13 11:29:23 DEBUG] [caching:25][39m Building activity cache...
[36m[2020-01-13 11:29:23 DEBUG] [caching:35][39m Cached 2 activities
[32m[2020-01-13 11:29:23 INFO] [experiment:54][39m Validating the experiment's syntax
[36m[2020-01-13 11:29:23 DEBUG] [configuration:36][39m Loading configuration...
[36m[2020-01-13 11:29:23 DEBUG] [secret:74][39m Loading secrets...
[36m[2020-01-13 11:29:23 DEBUG] [secret:89][39m Secrets loaded
[32m[2020-01-13 11:29:23 INFO] [experiment:100][39m Experiment looks valid
[36m[2020-01-13 11:29:23 DEBUG] [caching:42][39m Clearing activities cache
[36m[2020-01-13 11:29:23 DEBUG] [caching:25][39m Building activity cache...
[36m[2020-01-13 11:29:23 DEBUG] [caching:35][39m Cached 2 activities
[32m[2020-01-13 11:29:23 INFO] [experiment:179][39m Running experiment: Delay Movie Recommendation
[36m[2020-01-13 11:29:23 DEBUG] [configuration:36][39m Loading configuration...
[36m[2020-01-13 11:29:23 DEBUG] [secret:74][39m Loading secrets...
[36m[2020-01-13 11:29:23 DEBUG] [secret:89][39m Secrets loaded
[36m[2020-01-13 11:29:23 DEBUG] [__init__:39][39m Initializing controls
[36m[2020-01-13 11:29:23 DEBUG] [__init__:355][39m No controls to apply on 'experiment'
[32m[2020-01-13 11:29:23 INFO] [hypothesis:184][39m Steady state hypothesis: Movie recommendation in less than a second
[36m[2020-01-13 11:29:23 DEBUG] [__init__:355][39m No controls to apply on 'hypothesis'
[36m[2020-01-13 11:29:23 DEBUG] [__init__:355][39m No controls to apply on 'activity'
[32m[2020-01-13 11:29:23 INFO] [activity:158][39m Probe: we-can-request-sunset
[36m[2020-01-13 11:29:26 DEBUG] [activity:176][39m   => succeeded with '{'status': 200, 'headers': {'Content-Type': 'application/json', 'Transfer-Encoding': 'chunked', 'Date': 'Mon, 13 Jan 2020 10:29:26 GMT', 'Keep-Alive': 'timeout=60', 'Connection': 'keep-alive'}, 'body': {'title': 'Inception', 'duration': '2h 28m'}}'
[36m[2020-01-13 11:29:26 DEBUG] [__init__:355][39m No controls to apply on 'activity'
[36m[2020-01-13 11:29:26 DEBUG] [hypothesis:212][39m allowed tolerance is 200
[32m[2020-01-13 11:29:26 INFO] [hypothesis:222][39m Steady state hypothesis is met!
[36m[2020-01-13 11:29:26 DEBUG] [__init__:355][39m No controls to apply on 'hypothesis'
[36m[2020-01-13 11:29:26 DEBUG] [__init__:355][39m No controls to apply on 'method'
[36m[2020-01-13 11:29:26 DEBUG] [__init__:355][39m No controls to apply on 'activity'
[32m[2020-01-13 11:29:26 INFO] [activity:158][39m Action: enable_chaosmonkey
[36m[2020-01-13 11:29:26 DEBUG] [python:36][39m Activity 'enable_chaosmonkey' loaded from '/Users/john/.venvs/chaostk/lib/python3.7/site-packages/chaosspring/actions.py'
[36m[2020-01-13 11:29:26 DEBUG] [activity:176][39m   => succeeded with 'Chaos Monkey is enabled'
[36m[2020-01-13 11:29:26 DEBUG] [__init__:355][39m No controls to apply on 'activity'
[36m[2020-01-13 11:29:26 DEBUG] [__init__:355][39m No controls to apply on 'method'
[32m[2020-01-13 11:29:26 INFO] [hypothesis:184][39m Steady state hypothesis: Movie recommendation in less than a second
[36m[2020-01-13 11:29:26 DEBUG] [__init__:355][39m No controls to apply on 'hypothesis'
[36m[2020-01-13 11:29:26 DEBUG] [__init__:355][39m No controls to apply on 'activity'
[32m[2020-01-13 11:29:26 INFO] [activity:158][39m Probe: we-can-request-sunset
[36m[2020-01-13 11:29:29 DEBUG] [activity:176][39m   => succeeded with '{'status': 200, 'headers': {'Content-Type': 'application/json', 'Transfer-Encoding': 'chunked', 'Date': 'Mon, 13 Jan 2020 10:29:29 GMT', 'Keep-Alive': 'timeout=60', 'Connection': 'keep-alive'}, 'body': {'title': 'Inception', 'duration': '2h 28m'}}'
[36m[2020-01-13 11:29:29 DEBUG] [__init__:355][39m No controls to apply on 'activity'
[36m[2020-01-13 11:29:29 DEBUG] [hypothesis:212][39m allowed tolerance is 200
[32m[2020-01-13 11:29:29 INFO] [hypothesis:222][39m Steady state hypothesis is met!
[36m[2020-01-13 11:29:29 DEBUG] [__init__:355][39m No controls to apply on 'hypothesis'
[32m[2020-01-13 11:29:29 INFO] [experiment:320][39m Let's rollback...
[36m[2020-01-13 11:29:29 DEBUG] [__init__:355][39m No controls to apply on 'rollback'
[32m[2020-01-13 11:29:29 INFO] [rollback:25][39m No declared rollbacks, let's move on.
[36m[2020-01-13 11:29:29 DEBUG] [__init__:355][39m No controls to apply on 'rollback'
[32m[2020-01-13 11:29:29 INFO] [experiment:270][39m Experiment ended with status: completed
[36m[2020-01-13 11:29:29 DEBUG] [__init__:355][39m No controls to apply on 'experiment'
[36m[2020-01-13 11:29:29 DEBUG] [__init__:72][39m Cleaning up controls
[36m[2020-01-13 11:29:29 DEBUG] [caching:42][39m Clearing activities cache
[36m[2020-01-13 11:31:18 DEBUG] [cli:70][39m ###############################################################################
[36m[2020-01-13 11:31:18 DEBUG] [cli:71][39m Running command 'run'
[36m[2020-01-13 11:31:18 DEBUG] [cli:75][39m Using settings file '/Users/john/.chaostoolkit/settings.yaml'
[36m[2020-01-13 11:31:19 DEBUG] [settings:24][39m The Chaos Toolkit settings file could not be found at '/Users/john/.chaostoolkit/settings.yaml'.
[36m[2020-01-13 11:31:19 DEBUG] [__init__:355][39m No controls to apply on 'loader'
[36m[2020-01-13 11:31:19 DEBUG] [__init__:355][39m No controls to apply on 'loader'
[36m[2020-01-13 11:31:19 DEBUG] [caching:25][39m Building activity cache...
[36m[2020-01-13 11:31:19 DEBUG] [caching:35][39m Cached 2 activities
[32m[2020-01-13 11:31:19 INFO] [experiment:54][39m Validating the experiment's syntax
[36m[2020-01-13 11:31:19 DEBUG] [configuration:36][39m Loading configuration...
[36m[2020-01-13 11:31:19 DEBUG] [secret:74][39m Loading secrets...
[36m[2020-01-13 11:31:19 DEBUG] [secret:89][39m Secrets loaded
[32m[2020-01-13 11:31:19 INFO] [experiment:100][39m Experiment looks valid
[36m[2020-01-13 11:31:19 DEBUG] [caching:42][39m Clearing activities cache
[36m[2020-01-13 11:31:19 DEBUG] [caching:25][39m Building activity cache...
[36m[2020-01-13 11:31:19 DEBUG] [caching:35][39m Cached 2 activities
[32m[2020-01-13 11:31:19 INFO] [experiment:179][39m Running experiment: Delay Movie Recommendation
[36m[2020-01-13 11:31:19 DEBUG] [configuration:36][39m Loading configuration...
[36m[2020-01-13 11:31:19 DEBUG] [secret:74][39m Loading secrets...
[36m[2020-01-13 11:31:19 DEBUG] [secret:89][39m Secrets loaded
[36m[2020-01-13 11:31:19 DEBUG] [__init__:39][39m Initializing controls
[36m[2020-01-13 11:31:19 DEBUG] [__init__:355][39m No controls to apply on 'experiment'
[32m[2020-01-13 11:31:19 INFO] [hypothesis:184][39m Steady state hypothesis: Movie recommendation in less than a second
[36m[2020-01-13 11:31:19 DEBUG] [__init__:355][39m No controls to apply on 'hypothesis'
[36m[2020-01-13 11:31:19 DEBUG] [__init__:355][39m No controls to apply on 'activity'
[32m[2020-01-13 11:31:19 INFO] [activity:158][39m Probe: we-can-request-sunset
[36m[2020-01-13 11:31:22 DEBUG] [activity:176][39m   => succeeded with '{'status': 200, 'headers': {'Content-Type': 'application/json', 'Transfer-Encoding': 'chunked', 'Date': 'Mon, 13 Jan 2020 10:31:22 GMT', 'Keep-Alive': 'timeout=60', 'Connection': 'keep-alive'}, 'body': {'title': 'Inception', 'duration': '2h 28m'}}'
[36m[2020-01-13 11:31:22 DEBUG] [__init__:355][39m No controls to apply on 'activity'
[36m[2020-01-13 11:31:22 DEBUG] [hypothesis:212][39m allowed tolerance is 200
[32m[2020-01-13 11:31:22 INFO] [hypothesis:222][39m Steady state hypothesis is met!
[36m[2020-01-13 11:31:22 DEBUG] [__init__:355][39m No controls to apply on 'hypothesis'
[36m[2020-01-13 11:31:22 DEBUG] [__init__:355][39m No controls to apply on 'method'
[36m[2020-01-13 11:31:22 DEBUG] [__init__:355][39m No controls to apply on 'activity'
[32m[2020-01-13 11:31:22 INFO] [activity:158][39m Action: enable_chaosmonkey
[36m[2020-01-13 11:31:22 DEBUG] [python:36][39m Activity 'enable_chaosmonkey' loaded from '/Users/john/.venvs/chaostk/lib/python3.7/site-packages/chaosspring/actions.py'
[36m[2020-01-13 11:31:22 DEBUG] [activity:176][39m   => succeeded with 'Chaos Monkey is enabled'
[36m[2020-01-13 11:31:22 DEBUG] [__init__:355][39m No controls to apply on 'activity'
[36m[2020-01-13 11:31:22 DEBUG] [__init__:355][39m No controls to apply on 'method'
[32m[2020-01-13 11:31:22 INFO] [hypothesis:184][39m Steady state hypothesis: Movie recommendation in less than a second
[36m[2020-01-13 11:31:22 DEBUG] [__init__:355][39m No controls to apply on 'hypothesis'
[36m[2020-01-13 11:31:22 DEBUG] [__init__:355][39m No controls to apply on 'activity'
[32m[2020-01-13 11:31:22 INFO] [activity:158][39m Probe: we-can-request-sunset
[36m[2020-01-13 11:31:25 DEBUG] [activity:176][39m   => succeeded with '{'status': 200, 'headers': {'Content-Type': 'application/json', 'Transfer-Encoding': 'chunked', 'Date': 'Mon, 13 Jan 2020 10:31:25 GMT', 'Keep-Alive': 'timeout=60', 'Connection': 'keep-alive'}, 'body': {'title': 'Inception', 'duration': '2h 28m'}}'
[36m[2020-01-13 11:31:25 DEBUG] [__init__:355][39m No controls to apply on 'activity'
[36m[2020-01-13 11:31:25 DEBUG] [hypothesis:212][39m allowed tolerance is 200
[32m[2020-01-13 11:31:25 INFO] [hypothesis:222][39m Steady state hypothesis is met!
[36m[2020-01-13 11:31:25 DEBUG] [__init__:355][39m No controls to apply on 'hypothesis'
[32m[2020-01-13 11:31:25 INFO] [experiment:320][39m Let's rollback...
[36m[2020-01-13 11:31:25 DEBUG] [__init__:355][39m No controls to apply on 'rollback'
[32m[2020-01-13 11:31:25 INFO] [rollback:28][39m Rollback: disable_chaosmonkey
[36m[2020-01-13 11:31:25 DEBUG] [__init__:355][39m No controls to apply on 'activity'
[32m[2020-01-13 11:31:25 INFO] [activity:158][39m Action: disable_chaosmonkey
[36m[2020-01-13 11:31:25 DEBUG] [python:36][39m Activity 'disable_chaosmonkey' loaded from '/Users/john/.venvs/chaostk/lib/python3.7/site-packages/chaosspring/actions.py'
[36m[2020-01-13 11:31:25 DEBUG] [activity:176][39m   => succeeded with 'Chaos Monkey is disabled'
[36m[2020-01-13 11:31:25 DEBUG] [__init__:355][39m No controls to apply on 'activity'
[36m[2020-01-13 11:31:25 DEBUG] [__init__:355][39m No controls to apply on 'rollback'
[32m[2020-01-13 11:31:25 INFO] [experiment:270][39m Experiment ended with status: completed
[36m[2020-01-13 11:31:25 DEBUG] [__init__:355][39m No controls to apply on 'experiment'
[36m[2020-01-13 11:31:25 DEBUG] [__init__:72][39m Cleaning up controls
[36m[2020-01-13 11:31:25 DEBUG] [caching:42][39m Clearing activities cache
[36m[2020-01-13 12:26:44 DEBUG] [cli:70][39m ###############################################################################
[36m[2020-01-13 12:26:44 DEBUG] [cli:71][39m Running command 'run'
[36m[2020-01-13 12:26:44 DEBUG] [cli:75][39m Using settings file '/Users/john/.chaostoolkit/settings.yaml'
[36m[2020-01-13 12:26:45 DEBUG] [settings:24][39m The Chaos Toolkit settings file could not be found at '/Users/john/.chaostoolkit/settings.yaml'.
[36m[2020-01-13 12:26:45 DEBUG] [__init__:355][39m No controls to apply on 'loader'
[36m[2020-01-13 12:26:45 DEBUG] [__init__:355][39m No controls to apply on 'loader'
[36m[2020-01-13 12:26:45 DEBUG] [caching:25][39m Building activity cache...
[36m[2020-01-13 12:26:45 DEBUG] [caching:35][39m Cached 2 activities
[32m[2020-01-13 12:26:45 INFO] [experiment:54][39m Validating the experiment's syntax
[36m[2020-01-13 12:26:45 DEBUG] [configuration:36][39m Loading configuration...
[36m[2020-01-13 12:26:45 DEBUG] [secret:74][39m Loading secrets...
[36m[2020-01-13 12:26:45 DEBUG] [secret:89][39m Secrets loaded
[32m[2020-01-13 12:26:45 INFO] [experiment:100][39m Experiment looks valid
[36m[2020-01-13 12:26:45 DEBUG] [caching:42][39m Clearing activities cache
[36m[2020-01-13 12:26:45 DEBUG] [caching:25][39m Building activity cache...
[36m[2020-01-13 12:26:45 DEBUG] [caching:35][39m Cached 2 activities
[32m[2020-01-13 12:26:45 INFO] [experiment:179][39m Running experiment: Delay Movie Recommendation
[36m[2020-01-13 12:26:45 DEBUG] [configuration:36][39m Loading configuration...
[36m[2020-01-13 12:26:45 DEBUG] [secret:74][39m Loading secrets...
[36m[2020-01-13 12:26:45 DEBUG] [secret:89][39m Secrets loaded
[36m[2020-01-13 12:26:45 DEBUG] [__init__:39][39m Initializing controls
[36m[2020-01-13 12:26:45 DEBUG] [__init__:355][39m No controls to apply on 'experiment'
[32m[2020-01-13 12:26:45 INFO] [hypothesis:184][39m Steady state hypothesis: Movie recommendation in less than a second
[36m[2020-01-13 12:26:45 DEBUG] [__init__:355][39m No controls to apply on 'hypothesis'
[36m[2020-01-13 12:26:45 DEBUG] [__init__:355][39m No controls to apply on 'activity'
[32m[2020-01-13 12:26:45 INFO] [activity:158][39m Probe: we-can-request-sunset
[36m[2020-01-13 12:26:48 DEBUG] [activity:176][39m   => succeeded with '{'status': 200, 'headers': {'Content-Type': 'application/json', 'Transfer-Encoding': 'chunked', 'Date': 'Mon, 13 Jan 2020 11:26:48 GMT', 'Keep-Alive': 'timeout=60', 'Connection': 'keep-alive'}, 'body': {'title': 'Inception', 'duration': '2h 28m'}}'
[36m[2020-01-13 12:26:48 DEBUG] [__init__:355][39m No controls to apply on 'activity'
[36m[2020-01-13 12:26:48 DEBUG] [hypothesis:212][39m allowed tolerance is 200
[32m[2020-01-13 12:26:48 INFO] [hypothesis:222][39m Steady state hypothesis is met!
[36m[2020-01-13 12:26:48 DEBUG] [__init__:355][39m No controls to apply on 'hypothesis'
[36m[2020-01-13 12:26:48 DEBUG] [__init__:355][39m No controls to apply on 'method'
[36m[2020-01-13 12:26:48 DEBUG] [__init__:355][39m No controls to apply on 'activity'
[32m[2020-01-13 12:26:48 INFO] [activity:158][39m Action: enable_chaosmonkey
[36m[2020-01-13 12:26:48 DEBUG] [python:36][39m Activity 'enable_chaosmonkey' loaded from '/Users/john/.venvs/chaostk/lib/python3.7/site-packages/chaosspring/actions.py'
[36m[2020-01-13 12:26:48 DEBUG] [activity:176][39m   => succeeded with 'Chaos Monkey is enabled'
[36m[2020-01-13 12:26:48 DEBUG] [__init__:355][39m No controls to apply on 'activity'
[36m[2020-01-13 12:26:48 DEBUG] [__init__:355][39m No controls to apply on 'method'
[32m[2020-01-13 12:26:48 INFO] [hypothesis:184][39m Steady state hypothesis: Movie recommendation in less than a second
[36m[2020-01-13 12:26:48 DEBUG] [__init__:355][39m No controls to apply on 'hypothesis'
[36m[2020-01-13 12:26:48 DEBUG] [__init__:355][39m No controls to apply on 'activity'
[32m[2020-01-13 12:26:48 INFO] [activity:158][39m Probe: we-can-request-sunset
[36m[2020-01-13 12:26:51 DEBUG] [activity:176][39m   => succeeded with '{'status': 200, 'headers': {'Content-Type': 'application/json', 'Transfer-Encoding': 'chunked', 'Date': 'Mon, 13 Jan 2020 11:26:51 GMT', 'Keep-Alive': 'timeout=60', 'Connection': 'keep-alive'}, 'body': {'title': 'Inception', 'duration': '2h 28m'}}'
[36m[2020-01-13 12:26:51 DEBUG] [__init__:355][39m No controls to apply on 'activity'
[36m[2020-01-13 12:26:51 DEBUG] [hypothesis:212][39m allowed tolerance is 200
[32m[2020-01-13 12:26:51 INFO] [hypothesis:222][39m Steady state hypothesis is met!
[36m[2020-01-13 12:26:51 DEBUG] [__init__:355][39m No controls to apply on 'hypothesis'
[32m[2020-01-13 12:26:51 INFO] [experiment:320][39m Let's rollback...
[36m[2020-01-13 12:26:51 DEBUG] [__init__:355][39m No controls to apply on 'rollback'
[32m[2020-01-13 12:26:51 INFO] [rollback:28][39m Rollback: disable_chaosmonkey
[36m[2020-01-13 12:26:51 DEBUG] [__init__:355][39m No controls to apply on 'activity'
[32m[2020-01-13 12:26:51 INFO] [activity:158][39m Action: disable_chaosmonkey
[36m[2020-01-13 12:26:51 DEBUG] [python:36][39m Activity 'disable_chaosmonkey' loaded from '/Users/john/.venvs/chaostk/lib/python3.7/site-packages/chaosspring/actions.py'
[36m[2020-01-13 12:26:51 DEBUG] [activity:176][39m   => succeeded with 'Chaos Monkey is disabled'
[36m[2020-01-13 12:26:51 DEBUG] [__init__:355][39m No controls to apply on 'activity'
[36m[2020-01-13 12:26:51 DEBUG] [__init__:355][39m No controls to apply on 'rollback'
[32m[2020-01-13 12:26:51 INFO] [experiment:270][39m Experiment ended with status: completed
[36m[2020-01-13 12:26:51 DEBUG] [__init__:355][39m No controls to apply on 'experiment'
[36m[2020-01-13 12:26:51 DEBUG] [__init__:72][39m Cleaning up controls
[36m[2020-01-13 12:26:51 DEBUG] [caching:42][39m Clearing activities cache
[36m[2020-01-13 12:26:54 DEBUG] [cli:70][39m ###############################################################################
[36m[2020-01-13 12:26:54 DEBUG] [cli:71][39m Running command 'run'
[36m[2020-01-13 12:26:54 DEBUG] [cli:75][39m Using settings file '/Users/john/.chaostoolkit/settings.yaml'
[36m[2020-01-13 12:26:54 DEBUG] [settings:24][39m The Chaos Toolkit settings file could not be found at '/Users/john/.chaostoolkit/settings.yaml'.
[36m[2020-01-13 12:26:54 DEBUG] [__init__:355][39m No controls to apply on 'loader'
[36m[2020-01-13 12:26:54 DEBUG] [__init__:355][39m No controls to apply on 'loader'
[36m[2020-01-13 12:26:54 DEBUG] [caching:25][39m Building activity cache...
[36m[2020-01-13 12:26:54 DEBUG] [caching:35][39m Cached 2 activities
[32m[2020-01-13 12:26:54 INFO] [experiment:54][39m Validating the experiment's syntax
[36m[2020-01-13 12:26:54 DEBUG] [configuration:36][39m Loading configuration...
[36m[2020-01-13 12:26:54 DEBUG] [secret:74][39m Loading secrets...
[36m[2020-01-13 12:26:54 DEBUG] [secret:89][39m Secrets loaded
[32m[2020-01-13 12:26:54 INFO] [experiment:100][39m Experiment looks valid
[36m[2020-01-13 12:26:54 DEBUG] [caching:42][39m Clearing activities cache
[36m[2020-01-13 12:26:54 DEBUG] [caching:25][39m Building activity cache...
[36m[2020-01-13 12:26:54 DEBUG] [caching:35][39m Cached 2 activities
[32m[2020-01-13 12:26:54 INFO] [experiment:179][39m Running experiment: Delay Movie Recommendation
[36m[2020-01-13 12:26:54 DEBUG] [configuration:36][39m Loading configuration...
[36m[2020-01-13 12:26:54 DEBUG] [secret:74][39m Loading secrets...
[36m[2020-01-13 12:26:54 DEBUG] [secret:89][39m Secrets loaded
[36m[2020-01-13 12:26:54 DEBUG] [__init__:39][39m Initializing controls
[36m[2020-01-13 12:26:54 DEBUG] [__init__:355][39m No controls to apply on 'experiment'
[32m[2020-01-13 12:26:54 INFO] [hypothesis:184][39m Steady state hypothesis: Movie recommendation in less than a second
[36m[2020-01-13 12:26:54 DEBUG] [__init__:355][39m No controls to apply on 'hypothesis'
[36m[2020-01-13 12:26:54 DEBUG] [__init__:355][39m No controls to apply on 'activity'
[32m[2020-01-13 12:26:54 INFO] [activity:158][39m Probe: we-can-request-sunset
[36m[2020-01-13 12:26:54 DEBUG] [activity:176][39m   => succeeded with '{'status': 200, 'headers': {'Content-Type': 'application/json', 'Transfer-Encoding': 'chunked', 'Date': 'Mon, 13 Jan 2020 11:26:54 GMT', 'Keep-Alive': 'timeout=60', 'Connection': 'keep-alive'}, 'body': {'title': 'Inception', 'duration': '2h 28m'}}'
[36m[2020-01-13 12:26:54 DEBUG] [__init__:355][39m No controls to apply on 'activity'
[36m[2020-01-13 12:26:54 DEBUG] [hypothesis:212][39m allowed tolerance is 200
[32m[2020-01-13 12:26:54 INFO] [hypothesis:222][39m Steady state hypothesis is met!
[36m[2020-01-13 12:26:54 DEBUG] [__init__:355][39m No controls to apply on 'hypothesis'
[36m[2020-01-13 12:26:54 DEBUG] [__init__:355][39m No controls to apply on 'method'
[36m[2020-01-13 12:26:54 DEBUG] [__init__:355][39m No controls to apply on 'activity'
[32m[2020-01-13 12:26:54 INFO] [activity:158][39m Action: enable_chaosmonkey
[36m[2020-01-13 12:26:54 DEBUG] [python:36][39m Activity 'enable_chaosmonkey' loaded from '/Users/john/.venvs/chaostk/lib/python3.7/site-packages/chaosspring/actions.py'
[36m[2020-01-13 12:26:54 DEBUG] [activity:176][39m   => succeeded with 'Chaos Monkey is enabled'
[36m[2020-01-13 12:26:54 DEBUG] [__init__:355][39m No controls to apply on 'activity'
[36m[2020-01-13 12:26:54 DEBUG] [__init__:355][39m No controls to apply on 'method'
[32m[2020-01-13 12:26:54 INFO] [hypothesis:184][39m Steady state hypothesis: Movie recommendation in less than a second
[36m[2020-01-13 12:26:54 DEBUG] [__init__:355][39m No controls to apply on 'hypothesis'
[36m[2020-01-13 12:26:54 DEBUG] [__init__:355][39m No controls to apply on 'activity'
[32m[2020-01-13 12:26:54 INFO] [activity:158][39m Probe: we-can-request-sunset
[36m[2020-01-13 12:26:57 DEBUG] [activity:176][39m   => succeeded with '{'status': 200, 'headers': {'Content-Type': 'application/json', 'Transfer-Encoding': 'chunked', 'Date': 'Mon, 13 Jan 2020 11:26:57 GMT', 'Keep-Alive': 'timeout=60', 'Connection': 'keep-alive'}, 'body': {'title': 'Inception', 'duration': '2h 28m'}}'
[36m[2020-01-13 12:26:57 DEBUG] [__init__:355][39m No controls to apply on 'activity'
[36m[2020-01-13 12:26:57 DEBUG] [hypothesis:212][39m allowed tolerance is 200
[32m[2020-01-13 12:26:57 INFO] [hypothesis:222][39m Steady state hypothesis is met!
[36m[2020-01-13 12:26:57 DEBUG] [__init__:355][39m No controls to apply on 'hypothesis'
[32m[2020-01-13 12:26:57 INFO] [experiment:320][39m Let's rollback...
[36m[2020-01-13 12:26:57 DEBUG] [__init__:355][39m No controls to apply on 'rollback'
[32m[2020-01-13 12:26:57 INFO] [rollback:28][39m Rollback: disable_chaosmonkey
[36m[2020-01-13 12:26:57 DEBUG] [__init__:355][39m No controls to apply on 'activity'
[32m[2020-01-13 12:26:57 INFO] [activity:158][39m Action: disable_chaosmonkey
[36m[2020-01-13 12:26:57 DEBUG] [python:36][39m Activity 'disable_chaosmonkey' loaded from '/Users/john/.venvs/chaostk/lib/python3.7/site-packages/chaosspring/actions.py'
[36m[2020-01-13 12:26:57 DEBUG] [activity:176][39m   => succeeded with 'Chaos Monkey is disabled'
[36m[2020-01-13 12:26:57 DEBUG] [__init__:355][39m No controls to apply on 'activity'
[36m[2020-01-13 12:26:57 DEBUG] [__init__:355][39m No controls to apply on 'rollback'
[32m[2020-01-13 12:26:57 INFO] [experiment:270][39m Experiment ended with status: completed
[36m[2020-01-13 12:26:57 DEBUG] [__init__:355][39m No controls to apply on 'experiment'
[36m[2020-01-13 12:26:57 DEBUG] [__init__:72][39m Cleaning up controls
[36m[2020-01-13 12:26:57 DEBUG] [caching:42][39m Clearing activities cache
[36m[2020-01-13 12:27:20 DEBUG] [cli:70][39m ###############################################################################
[36m[2020-01-13 12:27:20 DEBUG] [cli:71][39m Running command 'run'
[36m[2020-01-13 12:27:20 DEBUG] [cli:75][39m Using settings file '/Users/john/.chaostoolkit/settings.yaml'
[36m[2020-01-13 12:27:21 DEBUG] [settings:24][39m The Chaos Toolkit settings file could not be found at '/Users/john/.chaostoolkit/settings.yaml'.
[36m[2020-01-13 12:27:21 DEBUG] [__init__:355][39m No controls to apply on 'loader'
[36m[2020-01-13 12:27:21 DEBUG] [__init__:355][39m No controls to apply on 'loader'
[36m[2020-01-13 12:27:21 DEBUG] [caching:25][39m Building activity cache...
[36m[2020-01-13 12:27:21 DEBUG] [caching:35][39m Cached 2 activities
[32m[2020-01-13 12:27:21 INFO] [experiment:54][39m Validating the experiment's syntax
[36m[2020-01-13 12:27:21 DEBUG] [configuration:36][39m Loading configuration...
[36m[2020-01-13 12:27:21 DEBUG] [secret:74][39m Loading secrets...
[36m[2020-01-13 12:27:21 DEBUG] [secret:89][39m Secrets loaded
[32m[2020-01-13 12:27:21 INFO] [experiment:100][39m Experiment looks valid
[36m[2020-01-13 12:27:21 DEBUG] [caching:42][39m Clearing activities cache
[36m[2020-01-13 12:27:21 DEBUG] [caching:25][39m Building activity cache...
[36m[2020-01-13 12:27:21 DEBUG] [caching:35][39m Cached 2 activities
[32m[2020-01-13 12:27:21 INFO] [experiment:179][39m Running experiment: Delay Movie Recommendation
[36m[2020-01-13 12:27:21 DEBUG] [configuration:36][39m Loading configuration...
[36m[2020-01-13 12:27:21 DEBUG] [secret:74][39m Loading secrets...
[36m[2020-01-13 12:27:21 DEBUG] [secret:89][39m Secrets loaded
[36m[2020-01-13 12:27:21 DEBUG] [__init__:39][39m Initializing controls
[36m[2020-01-13 12:27:21 DEBUG] [__init__:355][39m No controls to apply on 'experiment'
[32m[2020-01-13 12:27:21 INFO] [hypothesis:184][39m Steady state hypothesis: Movie recommendation in less than a second
[36m[2020-01-13 12:27:21 DEBUG] [__init__:355][39m No controls to apply on 'hypothesis'
[36m[2020-01-13 12:27:21 DEBUG] [__init__:355][39m No controls to apply on 'activity'
[32m[2020-01-13 12:27:21 INFO] [activity:158][39m Probe: we-can-request-sunset
[36m[2020-01-13 12:27:21 DEBUG] [activity:176][39m   => succeeded with '{'status': 200, 'headers': {'Content-Type': 'application/json', 'Transfer-Encoding': 'chunked', 'Date': 'Mon, 13 Jan 2020 11:27:21 GMT', 'Keep-Alive': 'timeout=60', 'Connection': 'keep-alive'}, 'body': {'title': 'Inception', 'duration': '2h 28m'}}'
[36m[2020-01-13 12:27:21 DEBUG] [__init__:355][39m No controls to apply on 'activity'
[36m[2020-01-13 12:27:21 DEBUG] [hypothesis:212][39m allowed tolerance is 201
[36m[2020-01-13 12:27:21 DEBUG] [__init__:355][39m No controls to apply on 'hypothesis'
[2020-01-13 12:27:21 CRITICAL] [experiment:215] Steady state probe 'we-can-request-sunset' is not in the given tolerance so failing this experiment
[32m[2020-01-13 12:27:21 INFO] [experiment:320][39m Let's rollback...
[36m[2020-01-13 12:27:21 DEBUG] [__init__:355][39m No controls to apply on 'rollback'
[32m[2020-01-13 12:27:21 INFO] [rollback:28][39m Rollback: disable_chaosmonkey
[36m[2020-01-13 12:27:21 DEBUG] [__init__:355][39m No controls to apply on 'activity'
[32m[2020-01-13 12:27:21 INFO] [activity:158][39m Action: disable_chaosmonkey
[36m[2020-01-13 12:27:21 DEBUG] [python:36][39m Activity 'disable_chaosmonkey' loaded from '/Users/john/.venvs/chaostk/lib/python3.7/site-packages/chaosspring/actions.py'
[36m[2020-01-13 12:27:21 DEBUG] [activity:176][39m   => succeeded with 'Chaos Monkey is disabled'
[36m[2020-01-13 12:27:21 DEBUG] [__init__:355][39m No controls to apply on 'activity'
[36m[2020-01-13 12:27:21 DEBUG] [__init__:355][39m No controls to apply on 'rollback'
[32m[2020-01-13 12:27:21 INFO] [experiment:270][39m Experiment ended with status: failed
[36m[2020-01-13 12:27:21 DEBUG] [__init__:355][39m No controls to apply on 'experiment'
[36m[2020-01-13 12:27:21 DEBUG] [__init__:72][39m Cleaning up controls
[36m[2020-01-13 12:27:21 DEBUG] [caching:42][39m Clearing activities cache
[36m[2020-01-13 12:27:50 DEBUG] [cli:70][39m ###############################################################################
[36m[2020-01-13 12:27:50 DEBUG] [cli:71][39m Running command 'run'
[36m[2020-01-13 12:27:50 DEBUG] [cli:75][39m Using settings file '/Users/john/.chaostoolkit/settings.yaml'
[36m[2020-01-13 12:27:51 DEBUG] [settings:24][39m The Chaos Toolkit settings file could not be found at '/Users/john/.chaostoolkit/settings.yaml'.
[36m[2020-01-13 12:27:51 DEBUG] [__init__:355][39m No controls to apply on 'loader'
[36m[2020-01-13 12:27:51 DEBUG] [__init__:355][39m No controls to apply on 'loader'
[36m[2020-01-13 12:27:51 DEBUG] [caching:25][39m Building activity cache...
[36m[2020-01-13 12:27:51 DEBUG] [caching:35][39m Cached 2 activities
[32m[2020-01-13 12:27:51 INFO] [experiment:54][39m Validating the experiment's syntax
[36m[2020-01-13 12:27:51 DEBUG] [configuration:36][39m Loading configuration...
[36m[2020-01-13 12:27:51 DEBUG] [secret:74][39m Loading secrets...
[36m[2020-01-13 12:27:51 DEBUG] [secret:89][39m Secrets loaded
[32m[2020-01-13 12:27:51 INFO] [experiment:100][39m Experiment looks valid
[36m[2020-01-13 12:27:51 DEBUG] [caching:42][39m Clearing activities cache
[36m[2020-01-13 12:27:51 DEBUG] [caching:25][39m Building activity cache...
[36m[2020-01-13 12:27:51 DEBUG] [caching:35][39m Cached 2 activities
[32m[2020-01-13 12:27:51 INFO] [experiment:179][39m Running experiment: Delay Movie Recommendation
[36m[2020-01-13 12:27:51 DEBUG] [configuration:36][39m Loading configuration...
[36m[2020-01-13 12:27:51 DEBUG] [secret:74][39m Loading secrets...
[36m[2020-01-13 12:27:51 DEBUG] [secret:89][39m Secrets loaded
[36m[2020-01-13 12:27:51 DEBUG] [__init__:39][39m Initializing controls
[36m[2020-01-13 12:27:51 DEBUG] [__init__:355][39m No controls to apply on 'experiment'
[32m[2020-01-13 12:27:51 INFO] [hypothesis:184][39m Steady state hypothesis: Movie recommendation in less than a second
[36m[2020-01-13 12:27:51 DEBUG] [__init__:355][39m No controls to apply on 'hypothesis'
[36m[2020-01-13 12:27:51 DEBUG] [__init__:355][39m No controls to apply on 'activity'
[32m[2020-01-13 12:27:51 INFO] [activity:158][39m Probe: we-can-request-sunset
[36m[2020-01-13 12:27:51 DEBUG] [activity:176][39m   => succeeded with '{'status': 200, 'headers': {'Content-Type': 'application/json', 'Transfer-Encoding': 'chunked', 'Date': 'Mon, 13 Jan 2020 11:27:51 GMT', 'Keep-Alive': 'timeout=60', 'Connection': 'keep-alive'}, 'body': {'title': 'Inception', 'duration': '2h 28m'}}'
[36m[2020-01-13 12:27:51 DEBUG] [__init__:355][39m No controls to apply on 'activity'
[36m[2020-01-13 12:27:51 DEBUG] [hypothesis:212][39m allowed tolerance is 200
[32m[2020-01-13 12:27:51 INFO] [hypothesis:222][39m Steady state hypothesis is met!
[36m[2020-01-13 12:27:51 DEBUG] [__init__:355][39m No controls to apply on 'hypothesis'
[36m[2020-01-13 12:27:51 DEBUG] [__init__:355][39m No controls to apply on 'method'
[36m[2020-01-13 12:27:51 DEBUG] [__init__:355][39m No controls to apply on 'activity'
[32m[2020-01-13 12:27:51 INFO] [activity:158][39m Action: enable_chaosmonkey
[36m[2020-01-13 12:27:51 DEBUG] [python:36][39m Activity 'enable_chaosmonkey' loaded from '/Users/john/.venvs/chaostk/lib/python3.7/site-packages/chaosspring/actions.py'
[36m[2020-01-13 12:27:51 DEBUG] [activity:176][39m   => succeeded with 'Chaos Monkey is enabled'
[36m[2020-01-13 12:27:51 DEBUG] [__init__:355][39m No controls to apply on 'activity'
[36m[2020-01-13 12:27:51 DEBUG] [__init__:355][39m No controls to apply on 'method'
[32m[2020-01-13 12:27:51 INFO] [hypothesis:184][39m Steady state hypothesis: Movie recommendation in less than a second
[36m[2020-01-13 12:27:51 DEBUG] [__init__:355][39m No controls to apply on 'hypothesis'
[36m[2020-01-13 12:27:51 DEBUG] [__init__:355][39m No controls to apply on 'activity'
[32m[2020-01-13 12:27:51 INFO] [activity:158][39m Probe: we-can-request-sunset
[36m[2020-01-13 12:27:54 DEBUG] [activity:176][39m   => succeeded with '{'status': 200, 'headers': {'Content-Type': 'application/json', 'Transfer-Encoding': 'chunked', 'Date': 'Mon, 13 Jan 2020 11:27:54 GMT', 'Keep-Alive': 'timeout=60', 'Connection': 'keep-alive'}, 'body': {'title': 'Inception', 'duration': '2h 28m'}}'
[36m[2020-01-13 12:27:54 DEBUG] [__init__:355][39m No controls to apply on 'activity'
[36m[2020-01-13 12:27:54 DEBUG] [hypothesis:212][39m allowed tolerance is 200
[32m[2020-01-13 12:27:54 INFO] [hypothesis:222][39m Steady state hypothesis is met!
[36m[2020-01-13 12:27:54 DEBUG] [__init__:355][39m No controls to apply on 'hypothesis'
[32m[2020-01-13 12:27:54 INFO] [experiment:320][39m Let's rollback...
[36m[2020-01-13 12:27:54 DEBUG] [__init__:355][39m No controls to apply on 'rollback'
[32m[2020-01-13 12:27:54 INFO] [rollback:28][39m Rollback: disable_chaosmonkey
[36m[2020-01-13 12:27:54 DEBUG] [__init__:355][39m No controls to apply on 'activity'
[32m[2020-01-13 12:27:54 INFO] [activity:158][39m Action: disable_chaosmonkey
[36m[2020-01-13 12:27:54 DEBUG] [python:36][39m Activity 'disable_chaosmonkey' loaded from '/Users/john/.venvs/chaostk/lib/python3.7/site-packages/chaosspring/actions.py'
[36m[2020-01-13 12:27:54 DEBUG] [activity:176][39m   => succeeded with 'Chaos Monkey is disabled'
[36m[2020-01-13 12:27:54 DEBUG] [__init__:355][39m No controls to apply on 'activity'
[36m[2020-01-13 12:27:54 DEBUG] [__init__:355][39m No controls to apply on 'rollback'
[32m[2020-01-13 12:27:54 INFO] [experiment:270][39m Experiment ended with status: completed
[36m[2020-01-13 12:27:54 DEBUG] [__init__:355][39m No controls to apply on 'experiment'
[36m[2020-01-13 12:27:54 DEBUG] [__init__:72][39m Cleaning up controls
[36m[2020-01-13 12:27:54 DEBUG] [caching:42][39m Clearing activities cache
[36m[2020-01-13 12:28:19 DEBUG] [cli:70][39m ###############################################################################
[36m[2020-01-13 12:28:19 DEBUG] [cli:71][39m Running command 'run'
[36m[2020-01-13 12:28:19 DEBUG] [cli:75][39m Using settings file '/Users/john/.chaostoolkit/settings.yaml'
[36m[2020-01-13 12:28:20 DEBUG] [settings:24][39m The Chaos Toolkit settings file could not be found at '/Users/john/.chaostoolkit/settings.yaml'.
[36m[2020-01-13 12:28:20 DEBUG] [__init__:355][39m No controls to apply on 'loader'
[36m[2020-01-13 12:28:20 DEBUG] [__init__:355][39m No controls to apply on 'loader'
[36m[2020-01-13 12:28:20 DEBUG] [caching:25][39m Building activity cache...
[36m[2020-01-13 12:28:20 DEBUG] [caching:35][39m Cached 2 activities
[32m[2020-01-13 12:28:20 INFO] [experiment:54][39m Validating the experiment's syntax
[36m[2020-01-13 12:28:20 DEBUG] [configuration:36][39m Loading configuration...
[36m[2020-01-13 12:28:20 DEBUG] [secret:74][39m Loading secrets...
[36m[2020-01-13 12:28:20 DEBUG] [secret:89][39m Secrets loaded
[32m[2020-01-13 12:28:20 INFO] [experiment:100][39m Experiment looks valid
[36m[2020-01-13 12:28:20 DEBUG] [caching:42][39m Clearing activities cache
[36m[2020-01-13 12:28:20 DEBUG] [caching:25][39m Building activity cache...
[36m[2020-01-13 12:28:20 DEBUG] [caching:35][39m Cached 2 activities
[32m[2020-01-13 12:28:20 INFO] [experiment:179][39m Running experiment: Delay Movie Recommendation
[36m[2020-01-13 12:28:20 DEBUG] [configuration:36][39m Loading configuration...
[36m[2020-01-13 12:28:20 DEBUG] [secret:74][39m Loading secrets...
[36m[2020-01-13 12:28:20 DEBUG] [secret:89][39m Secrets loaded
[36m[2020-01-13 12:28:20 DEBUG] [__init__:39][39m Initializing controls
[36m[2020-01-13 12:28:20 DEBUG] [__init__:355][39m No controls to apply on 'experiment'
[32m[2020-01-13 12:28:20 INFO] [hypothesis:184][39m Steady state hypothesis: Movie recommendation in less than a second
[36m[2020-01-13 12:28:20 DEBUG] [__init__:355][39m No controls to apply on 'hypothesis'
[36m[2020-01-13 12:28:20 DEBUG] [__init__:355][39m No controls to apply on 'activity'
[32m[2020-01-13 12:28:20 INFO] [activity:158][39m Probe: we-can-request-sunset
[36m[2020-01-13 12:28:20 DEBUG] [activity:176][39m   => succeeded with '{'status': 200, 'headers': {'Content-Type': 'application/json', 'Transfer-Encoding': 'chunked', 'Date': 'Mon, 13 Jan 2020 11:28:20 GMT', 'Keep-Alive': 'timeout=60', 'Connection': 'keep-alive'}, 'body': {'title': 'Inception', 'duration': '2h 28m'}}'
[36m[2020-01-13 12:28:20 DEBUG] [__init__:355][39m No controls to apply on 'activity'
[36m[2020-01-13 12:28:20 DEBUG] [hypothesis:212][39m allowed tolerance is 200
[32m[2020-01-13 12:28:20 INFO] [hypothesis:222][39m Steady state hypothesis is met!
[36m[2020-01-13 12:28:20 DEBUG] [__init__:355][39m No controls to apply on 'hypothesis'
[36m[2020-01-13 12:28:20 DEBUG] [__init__:355][39m No controls to apply on 'method'
[36m[2020-01-13 12:28:20 DEBUG] [__init__:355][39m No controls to apply on 'activity'
[32m[2020-01-13 12:28:20 INFO] [activity:158][39m Action: enable_chaosmonkey
[36m[2020-01-13 12:28:20 DEBUG] [python:36][39m Activity 'enable_chaosmonkey' loaded from '/Users/john/.venvs/chaostk/lib/python3.7/site-packages/chaosspring/actions.py'
[36m[2020-01-13 12:28:20 DEBUG] [activity:176][39m   => succeeded with 'Chaos Monkey is enabled'
[36m[2020-01-13 12:28:20 DEBUG] [__init__:355][39m No controls to apply on 'activity'
[36m[2020-01-13 12:28:20 DEBUG] [__init__:355][39m No controls to apply on 'method'
[32m[2020-01-13 12:28:20 INFO] [hypothesis:184][39m Steady state hypothesis: Movie recommendation in less than a second
[36m[2020-01-13 12:28:20 DEBUG] [__init__:355][39m No controls to apply on 'hypothesis'
[36m[2020-01-13 12:28:20 DEBUG] [__init__:355][39m No controls to apply on 'activity'
[32m[2020-01-13 12:28:20 INFO] [activity:158][39m Probe: we-can-request-sunset
[36m[2020-01-13 12:28:23 DEBUG] [activity:176][39m   => succeeded with '{'status': 200, 'headers': {'Content-Type': 'application/json', 'Transfer-Encoding': 'chunked', 'Date': 'Mon, 13 Jan 2020 11:28:23 GMT', 'Keep-Alive': 'timeout=60', 'Connection': 'keep-alive'}, 'body': {'title': 'Inception', 'duration': '2h 28m'}}'
[36m[2020-01-13 12:28:23 DEBUG] [__init__:355][39m No controls to apply on 'activity'
[36m[2020-01-13 12:28:23 DEBUG] [hypothesis:212][39m allowed tolerance is 200
[32m[2020-01-13 12:28:23 INFO] [hypothesis:222][39m Steady state hypothesis is met!
[36m[2020-01-13 12:28:23 DEBUG] [__init__:355][39m No controls to apply on 'hypothesis'
[32m[2020-01-13 12:28:23 INFO] [experiment:320][39m Let's rollback...
[36m[2020-01-13 12:28:23 DEBUG] [__init__:355][39m No controls to apply on 'rollback'
[32m[2020-01-13 12:28:23 INFO] [rollback:28][39m Rollback: disable_chaosmonkey
[36m[2020-01-13 12:28:23 DEBUG] [__init__:355][39m No controls to apply on 'activity'
[32m[2020-01-13 12:28:23 INFO] [activity:158][39m Action: disable_chaosmonkey
[36m[2020-01-13 12:28:23 DEBUG] [python:36][39m Activity 'disable_chaosmonkey' loaded from '/Users/john/.venvs/chaostk/lib/python3.7/site-packages/chaosspring/actions.py'
[36m[2020-01-13 12:28:23 DEBUG] [activity:176][39m   => succeeded with 'Chaos Monkey is disabled'
[36m[2020-01-13 12:28:23 DEBUG] [__init__:355][39m No controls to apply on 'activity'
[36m[2020-01-13 12:28:23 DEBUG] [__init__:355][39m No controls to apply on 'rollback'
[32m[2020-01-13 12:28:23 INFO] [experiment:270][39m Experiment ended with status: completed
[36m[2020-01-13 12:28:23 DEBUG] [__init__:355][39m No controls to apply on 'experiment'
[36m[2020-01-13 12:28:23 DEBUG] [__init__:72][39m Cleaning up controls
[36m[2020-01-13 12:28:23 DEBUG] [caching:42][39m Clearing activities cache
[36m[2020-01-13 12:28:28 DEBUG] [cli:70][39m ###############################################################################
[36m[2020-01-13 12:28:28 DEBUG] [cli:71][39m Running command 'run'
[36m[2020-01-13 12:28:28 DEBUG] [cli:75][39m Using settings file '/Users/john/.chaostoolkit/settings.yaml'
[36m[2020-01-13 12:28:29 DEBUG] [settings:24][39m The Chaos Toolkit settings file could not be found at '/Users/john/.chaostoolkit/settings.yaml'.
[36m[2020-01-13 12:28:29 DEBUG] [__init__:355][39m No controls to apply on 'loader'
[36m[2020-01-13 12:28:29 DEBUG] [__init__:355][39m No controls to apply on 'loader'
[36m[2020-01-13 12:28:29 DEBUG] [caching:25][39m Building activity cache...
[36m[2020-01-13 12:28:29 DEBUG] [caching:35][39m Cached 2 activities
[32m[2020-01-13 12:28:29 INFO] [experiment:54][39m Validating the experiment's syntax
[36m[2020-01-13 12:28:29 DEBUG] [configuration:36][39m Loading configuration...
[36m[2020-01-13 12:28:29 DEBUG] [secret:74][39m Loading secrets...
[36m[2020-01-13 12:28:29 DEBUG] [secret:89][39m Secrets loaded
[32m[2020-01-13 12:28:29 INFO] [experiment:100][39m Experiment looks valid
[36m[2020-01-13 12:28:29 DEBUG] [caching:42][39m Clearing activities cache
[36m[2020-01-13 12:28:29 DEBUG] [caching:25][39m Building activity cache...
[36m[2020-01-13 12:28:29 DEBUG] [caching:35][39m Cached 2 activities
[32m[2020-01-13 12:28:29 INFO] [experiment:179][39m Running experiment: Delay Movie Recommendation
[36m[2020-01-13 12:28:29 DEBUG] [configuration:36][39m Loading configuration...
[36m[2020-01-13 12:28:29 DEBUG] [secret:74][39m Loading secrets...
[36m[2020-01-13 12:28:29 DEBUG] [secret:89][39m Secrets loaded
[36m[2020-01-13 12:28:29 DEBUG] [__init__:39][39m Initializing controls
[36m[2020-01-13 12:28:29 DEBUG] [__init__:355][39m No controls to apply on 'experiment'
[32m[2020-01-13 12:28:29 INFO] [hypothesis:184][39m Steady state hypothesis: Movie recommendation in less than a second
[36m[2020-01-13 12:28:29 DEBUG] [__init__:355][39m No controls to apply on 'hypothesis'
[36m[2020-01-13 12:28:29 DEBUG] [__init__:355][39m No controls to apply on 'activity'
[32m[2020-01-13 12:28:29 INFO] [activity:158][39m Probe: we-can-request-sunset
[36m[2020-01-13 12:28:29 DEBUG] [activity:176][39m   => succeeded with '{'status': 200, 'headers': {'Content-Type': 'application/json', 'Transfer-Encoding': 'chunked', 'Date': 'Mon, 13 Jan 2020 11:28:29 GMT', 'Keep-Alive': 'timeout=60', 'Connection': 'keep-alive'}, 'body': {'title': 'Inception', 'duration': '2h 28m'}}'
[36m[2020-01-13 12:28:29 DEBUG] [__init__:355][39m No controls to apply on 'activity'
[36m[2020-01-13 12:28:29 DEBUG] [hypothesis:212][39m allowed tolerance is 200
[32m[2020-01-13 12:28:29 INFO] [hypothesis:222][39m Steady state hypothesis is met!
[36m[2020-01-13 12:28:29 DEBUG] [__init__:355][39m No controls to apply on 'hypothesis'
[36m[2020-01-13 12:28:29 DEBUG] [__init__:355][39m No controls to apply on 'method'
[36m[2020-01-13 12:28:29 DEBUG] [__init__:355][39m No controls to apply on 'activity'
[32m[2020-01-13 12:28:29 INFO] [activity:158][39m Action: enable_chaosmonkey
[36m[2020-01-13 12:28:29 DEBUG] [python:36][39m Activity 'enable_chaosmonkey' loaded from '/Users/john/.venvs/chaostk/lib/python3.7/site-packages/chaosspring/actions.py'
[36m[2020-01-13 12:28:29 DEBUG] [activity:176][39m   => succeeded with 'Chaos Monkey is enabled'
[36m[2020-01-13 12:28:29 DEBUG] [__init__:355][39m No controls to apply on 'activity'
[36m[2020-01-13 12:28:29 DEBUG] [__init__:355][39m No controls to apply on 'method'
[32m[2020-01-13 12:28:29 INFO] [hypothesis:184][39m Steady state hypothesis: Movie recommendation in less than a second
[36m[2020-01-13 12:28:29 DEBUG] [__init__:355][39m No controls to apply on 'hypothesis'
[36m[2020-01-13 12:28:29 DEBUG] [__init__:355][39m No controls to apply on 'activity'
[32m[2020-01-13 12:28:29 INFO] [activity:158][39m Probe: we-can-request-sunset
[36m[2020-01-13 12:28:30 DEBUG] [activity:230][39m Activity failed
    Traceback (most recent call last):
      File "/Users/john/.venvs/chaostk/lib/python3.7/site-packages/urllib3/connectionpool.py", line 421, in _make_request
        six.raise_from(e, None)
      File "<string>", line 3, in raise_from
      File "/Users/john/.venvs/chaostk/lib/python3.7/site-packages/urllib3/connectionpool.py", line 416, in _make_request
        httplib_response = conn.getresponse()
      File "/usr/local/Cellar/python/3.7.5/Frameworks/Python.framework/Versions/3.7/lib/python3.7/http/client.py", line 1344, in getresponse
        response.begin()
      File "/usr/local/Cellar/python/3.7.5/Frameworks/Python.framework/Versions/3.7/lib/python3.7/http/client.py", line 306, in begin
        version, status, reason = self._read_status()
      File "/usr/local/Cellar/python/3.7.5/Frameworks/Python.framework/Versions/3.7/lib/python3.7/http/client.py", line 267, in _read_status
        line = str(self.fp.readline(_MAXLINE + 1), "iso-8859-1")
      File "/usr/local/Cellar/python/3.7.5/Frameworks/Python.framework/Versions/3.7/lib/python3.7/socket.py", line 589, in readinto
        return self._sock.recv_into(b)
    socket.timeout: timed out
    
    During handling of the above exception, another exception occurred:
    
    Traceback (most recent call last):
      File "/Users/john/.venvs/chaostk/lib/python3.7/site-packages/requests/adapters.py", line 449, in send
        timeout=timeout
      File "/Users/john/.venvs/chaostk/lib/python3.7/site-packages/urllib3/connectionpool.py", line 720, in urlopen
        method, url, error=e, _pool=self, _stacktrace=sys.exc_info()[2]
      File "/Users/john/.venvs/chaostk/lib/python3.7/site-packages/urllib3/util/retry.py", line 400, in increment
        raise six.reraise(type(error), error, _stacktrace)
      File "/Users/john/.venvs/chaostk/lib/python3.7/site-packages/urllib3/packages/six.py", line 735, in reraise
        raise value
      File "/Users/john/.venvs/chaostk/lib/python3.7/site-packages/urllib3/connectionpool.py", line 672, in urlopen
        chunked=chunked,
      File "/Users/john/.venvs/chaostk/lib/python3.7/site-packages/urllib3/connectionpool.py", line 423, in _make_request
        self._raise_timeout(err=e, url=url, timeout_value=read_timeout)
      File "/Users/john/.venvs/chaostk/lib/python3.7/site-packages/urllib3/connectionpool.py", line 331, in _raise_timeout
        self, url, "Read timed out. (read timeout=%s)" % timeout_value
    urllib3.exceptions.ReadTimeoutError: HTTPConnectionPool(host='localhost', port=8080): Read timed out. (read timeout=1)
    
    During handling of the above exception, another exception occurred:
    
    Traceback (most recent call last):
      File "/Users/john/.venvs/chaostk/lib/python3.7/site-packages/chaoslib/provider/http.py", line 53, in run_http_activity
        verify=verify_tls)
      File "/Users/john/.venvs/chaostk/lib/python3.7/site-packages/requests/sessions.py", line 546, in get
        return self.request('GET', url, **kwargs)
      File "/Users/john/.venvs/chaostk/lib/python3.7/site-packages/requests/sessions.py", line 533, in request
        resp = self.send(prep, **send_kwargs)
      File "/Users/john/.venvs/chaostk/lib/python3.7/site-packages/requests/sessions.py", line 646, in send
        r = adapter.send(request, **kwargs)
      File "/Users/john/.venvs/chaostk/lib/python3.7/site-packages/requests/adapters.py", line 529, in send
        raise ReadTimeout(e, request=request)
    requests.exceptions.ReadTimeout: HTTPConnectionPool(host='localhost', port=8080): Read timed out. (read timeout=1)
    
    During handling of the above exception, another exception occurred:
    
    Traceback (most recent call last):
      File "/Users/john/.venvs/chaostk/lib/python3.7/site-packages/chaoslib/activity.py", line 227, in run_activity
        result = run_http_activity(activity, configuration, secrets)
      File "/Users/john/.venvs/chaostk/lib/python3.7/site-packages/chaoslib/provider/http.py", line 89, in run_http_activity
        raise ActivityFailed("activity took too long to complete")
    chaoslib.exceptions.ActivityFailed: activity took too long to complete
[31m[2020-01-13 12:28:30 ERROR] [activity:184][39m   => failed: activity took too long to complete
[36m[2020-01-13 12:28:30 DEBUG] [__init__:355][39m No controls to apply on 'activity'
[33m[2020-01-13 12:28:30 WARNING] [hypothesis:201][39m Probe terminated unexpectedly, so its tolerance could not be validated
[36m[2020-01-13 12:28:30 DEBUG] [__init__:355][39m No controls to apply on 'hypothesis'
[2020-01-13 12:28:30 CRITICAL] [experiment:241] Steady state probe 'we-can-request-sunset' is not in the given tolerance so failing this experiment
[32m[2020-01-13 12:28:30 INFO] [experiment:320][39m Let's rollback...
[36m[2020-01-13 12:28:30 DEBUG] [__init__:355][39m No controls to apply on 'rollback'
[32m[2020-01-13 12:28:30 INFO] [rollback:28][39m Rollback: disable_chaosmonkey
[36m[2020-01-13 12:28:30 DEBUG] [__init__:355][39m No controls to apply on 'activity'
[32m[2020-01-13 12:28:30 INFO] [activity:158][39m Action: disable_chaosmonkey
[36m[2020-01-13 12:28:30 DEBUG] [python:36][39m Activity 'disable_chaosmonkey' loaded from '/Users/john/.venvs/chaostk/lib/python3.7/site-packages/chaosspring/actions.py'
[36m[2020-01-13 12:28:30 DEBUG] [activity:176][39m   => succeeded with 'Chaos Monkey is disabled'
[36m[2020-01-13 12:28:30 DEBUG] [__init__:355][39m No controls to apply on 'activity'
[36m[2020-01-13 12:28:30 DEBUG] [__init__:355][39m No controls to apply on 'rollback'
[32m[2020-01-13 12:28:30 INFO] [experiment:270][39m Experiment ended with status: deviated
[32m[2020-01-13 12:28:30 INFO] [experiment:274][39m The steady-state has deviated, a weakness may have been discovered
[36m[2020-01-13 12:28:30 DEBUG] [__init__:355][39m No controls to apply on 'experiment'
[36m[2020-01-13 12:28:30 DEBUG] [__init__:72][39m Cleaning up controls
[36m[2020-01-13 12:28:30 DEBUG] [caching:42][39m Clearing activities cache
[36m[2020-01-13 12:28:56 DEBUG] [cli:70][39m ###############################################################################
[36m[2020-01-13 12:28:56 DEBUG] [cli:71][39m Running command 'run'
[36m[2020-01-13 12:28:56 DEBUG] [cli:75][39m Using settings file '/Users/john/.chaostoolkit/settings.yaml'
[36m[2020-01-13 12:28:57 DEBUG] [settings:24][39m The Chaos Toolkit settings file could not be found at '/Users/john/.chaostoolkit/settings.yaml'.
[36m[2020-01-13 12:28:57 DEBUG] [__init__:355][39m No controls to apply on 'loader'
[36m[2020-01-13 12:28:57 DEBUG] [__init__:355][39m No controls to apply on 'loader'
[36m[2020-01-13 12:28:57 DEBUG] [caching:25][39m Building activity cache...
[36m[2020-01-13 12:28:57 DEBUG] [caching:35][39m Cached 2 activities
[32m[2020-01-13 12:28:57 INFO] [experiment:54][39m Validating the experiment's syntax
[36m[2020-01-13 12:28:57 DEBUG] [configuration:36][39m Loading configuration...
[36m[2020-01-13 12:28:57 DEBUG] [secret:74][39m Loading secrets...
[36m[2020-01-13 12:28:57 DEBUG] [secret:89][39m Secrets loaded
[32m[2020-01-13 12:28:57 INFO] [experiment:100][39m Experiment looks valid
[36m[2020-01-13 12:28:57 DEBUG] [caching:42][39m Clearing activities cache
[36m[2020-01-13 12:28:57 DEBUG] [caching:25][39m Building activity cache...
[36m[2020-01-13 12:28:57 DEBUG] [caching:35][39m Cached 2 activities
[32m[2020-01-13 12:28:57 INFO] [experiment:179][39m Running experiment: Delay Movie Recommendation
[36m[2020-01-13 12:28:57 DEBUG] [configuration:36][39m Loading configuration...
[36m[2020-01-13 12:28:57 DEBUG] [secret:74][39m Loading secrets...
[36m[2020-01-13 12:28:57 DEBUG] [secret:89][39m Secrets loaded
[36m[2020-01-13 12:28:57 DEBUG] [__init__:39][39m Initializing controls
[36m[2020-01-13 12:28:57 DEBUG] [__init__:355][39m No controls to apply on 'experiment'
[32m[2020-01-13 12:28:57 INFO] [hypothesis:184][39m Steady state hypothesis: Movie recommendation in less than a second
[36m[2020-01-13 12:28:57 DEBUG] [__init__:355][39m No controls to apply on 'hypothesis'
[36m[2020-01-13 12:28:57 DEBUG] [__init__:355][39m No controls to apply on 'activity'
[32m[2020-01-13 12:28:57 INFO] [activity:158][39m Probe: we-can-request-sunset
[36m[2020-01-13 12:28:57 DEBUG] [activity:176][39m   => succeeded with '{'status': 200, 'headers': {'Content-Type': 'application/json', 'Transfer-Encoding': 'chunked', 'Date': 'Mon, 13 Jan 2020 11:28:57 GMT', 'Keep-Alive': 'timeout=60', 'Connection': 'keep-alive'}, 'body': {'title': 'Inception', 'duration': '2h 28m'}}'
[36m[2020-01-13 12:28:57 DEBUG] [__init__:355][39m No controls to apply on 'activity'
[36m[2020-01-13 12:28:57 DEBUG] [hypothesis:212][39m allowed tolerance is 200
[32m[2020-01-13 12:28:57 INFO] [hypothesis:222][39m Steady state hypothesis is met!
[36m[2020-01-13 12:28:57 DEBUG] [__init__:355][39m No controls to apply on 'hypothesis'
[36m[2020-01-13 12:28:57 DEBUG] [__init__:355][39m No controls to apply on 'method'
[36m[2020-01-13 12:28:57 DEBUG] [__init__:355][39m No controls to apply on 'activity'
[32m[2020-01-13 12:28:57 INFO] [activity:158][39m Action: enable_chaosmonkey
[36m[2020-01-13 12:28:57 DEBUG] [python:36][39m Activity 'enable_chaosmonkey' loaded from '/Users/john/.venvs/chaostk/lib/python3.7/site-packages/chaosspring/actions.py'
[36m[2020-01-13 12:28:57 DEBUG] [activity:176][39m   => succeeded with 'Chaos Monkey is enabled'
[36m[2020-01-13 12:28:57 DEBUG] [__init__:355][39m No controls to apply on 'activity'
[36m[2020-01-13 12:28:57 DEBUG] [__init__:355][39m No controls to apply on 'method'
[32m[2020-01-13 12:28:57 INFO] [hypothesis:184][39m Steady state hypothesis: Movie recommendation in less than a second
[36m[2020-01-13 12:28:57 DEBUG] [__init__:355][39m No controls to apply on 'hypothesis'
[36m[2020-01-13 12:28:57 DEBUG] [__init__:355][39m No controls to apply on 'activity'
[32m[2020-01-13 12:28:57 INFO] [activity:158][39m Probe: we-can-request-sunset
[36m[2020-01-13 12:28:57 DEBUG] [activity:230][39m Activity failed
    Traceback (most recent call last):
      File "/Users/john/.venvs/chaostk/lib/python3.7/site-packages/urllib3/connectionpool.py", line 421, in _make_request
        six.raise_from(e, None)
      File "<string>", line 3, in raise_from
      File "/Users/john/.venvs/chaostk/lib/python3.7/site-packages/urllib3/connectionpool.py", line 416, in _make_request
        httplib_response = conn.getresponse()
      File "/usr/local/Cellar/python/3.7.5/Frameworks/Python.framework/Versions/3.7/lib/python3.7/http/client.py", line 1344, in getresponse
        response.begin()
      File "/usr/local/Cellar/python/3.7.5/Frameworks/Python.framework/Versions/3.7/lib/python3.7/http/client.py", line 306, in begin
        version, status, reason = self._read_status()
      File "/usr/local/Cellar/python/3.7.5/Frameworks/Python.framework/Versions/3.7/lib/python3.7/http/client.py", line 267, in _read_status
        line = str(self.fp.readline(_MAXLINE + 1), "iso-8859-1")
      File "/usr/local/Cellar/python/3.7.5/Frameworks/Python.framework/Versions/3.7/lib/python3.7/socket.py", line 589, in readinto
        return self._sock.recv_into(b)
    socket.timeout: timed out
    
    During handling of the above exception, another exception occurred:
    
    Traceback (most recent call last):
      File "/Users/john/.venvs/chaostk/lib/python3.7/site-packages/requests/adapters.py", line 449, in send
        timeout=timeout
      File "/Users/john/.venvs/chaostk/lib/python3.7/site-packages/urllib3/connectionpool.py", line 720, in urlopen
        method, url, error=e, _pool=self, _stacktrace=sys.exc_info()[2]
      File "/Users/john/.venvs/chaostk/lib/python3.7/site-packages/urllib3/util/retry.py", line 400, in increment
        raise six.reraise(type(error), error, _stacktrace)
      File "/Users/john/.venvs/chaostk/lib/python3.7/site-packages/urllib3/packages/six.py", line 735, in reraise
        raise value
      File "/Users/john/.venvs/chaostk/lib/python3.7/site-packages/urllib3/connectionpool.py", line 672, in urlopen
        chunked=chunked,
      File "/Users/john/.venvs/chaostk/lib/python3.7/site-packages/urllib3/connectionpool.py", line 423, in _make_request
        self._raise_timeout(err=e, url=url, timeout_value=read_timeout)
      File "/Users/john/.venvs/chaostk/lib/python3.7/site-packages/urllib3/connectionpool.py", line 331, in _raise_timeout
        self, url, "Read timed out. (read timeout=%s)" % timeout_value
    urllib3.exceptions.ReadTimeoutError: HTTPConnectionPool(host='localhost', port=8080): Read timed out. (read timeout=0.1)
    
    During handling of the above exception, another exception occurred:
    
    Traceback (most recent call last):
      File "/Users/john/.venvs/chaostk/lib/python3.7/site-packages/chaoslib/provider/http.py", line 53, in run_http_activity
        verify=verify_tls)
      File "/Users/john/.venvs/chaostk/lib/python3.7/site-packages/requests/sessions.py", line 546, in get
        return self.request('GET', url, **kwargs)
      File "/Users/john/.venvs/chaostk/lib/python3.7/site-packages/requests/sessions.py", line 533, in request
        resp = self.send(prep, **send_kwargs)
      File "/Users/john/.venvs/chaostk/lib/python3.7/site-packages/requests/sessions.py", line 646, in send
        r = adapter.send(request, **kwargs)
      File "/Users/john/.venvs/chaostk/lib/python3.7/site-packages/requests/adapters.py", line 529, in send
        raise ReadTimeout(e, request=request)
    requests.exceptions.ReadTimeout: HTTPConnectionPool(host='localhost', port=8080): Read timed out. (read timeout=0.1)
    
    During handling of the above exception, another exception occurred:
    
    Traceback (most recent call last):
      File "/Users/john/.venvs/chaostk/lib/python3.7/site-packages/chaoslib/activity.py", line 227, in run_activity
        result = run_http_activity(activity, configuration, secrets)
      File "/Users/john/.venvs/chaostk/lib/python3.7/site-packages/chaoslib/provider/http.py", line 89, in run_http_activity
        raise ActivityFailed("activity took too long to complete")
    chaoslib.exceptions.ActivityFailed: activity took too long to complete
[31m[2020-01-13 12:28:57 ERROR] [activity:184][39m   => failed: activity took too long to complete
[36m[2020-01-13 12:28:57 DEBUG] [__init__:355][39m No controls to apply on 'activity'
[33m[2020-01-13 12:28:57 WARNING] [hypothesis:201][39m Probe terminated unexpectedly, so its tolerance could not be validated
[36m[2020-01-13 12:28:57 DEBUG] [__init__:355][39m No controls to apply on 'hypothesis'
[2020-01-13 12:28:57 CRITICAL] [experiment:241] Steady state probe 'we-can-request-sunset' is not in the given tolerance so failing this experiment
[32m[2020-01-13 12:28:57 INFO] [experiment:320][39m Let's rollback...
[36m[2020-01-13 12:28:57 DEBUG] [__init__:355][39m No controls to apply on 'rollback'
[32m[2020-01-13 12:28:57 INFO] [rollback:28][39m Rollback: disable_chaosmonkey
[36m[2020-01-13 12:28:57 DEBUG] [__init__:355][39m No controls to apply on 'activity'
[32m[2020-01-13 12:28:57 INFO] [activity:158][39m Action: disable_chaosmonkey
[36m[2020-01-13 12:28:57 DEBUG] [python:36][39m Activity 'disable_chaosmonkey' loaded from '/Users/john/.venvs/chaostk/lib/python3.7/site-packages/chaosspring/actions.py'
[36m[2020-01-13 12:28:57 DEBUG] [activity:176][39m   => succeeded with 'Chaos Monkey is disabled'
[36m[2020-01-13 12:28:57 DEBUG] [__init__:355][39m No controls to apply on 'activity'
[36m[2020-01-13 12:28:57 DEBUG] [__init__:355][39m No controls to apply on 'rollback'
[32m[2020-01-13 12:28:57 INFO] [experiment:270][39m Experiment ended with status: deviated
[32m[2020-01-13 12:28:57 INFO] [experiment:274][39m The steady-state has deviated, a weakness may have been discovered
[36m[2020-01-13 12:28:57 DEBUG] [__init__:355][39m No controls to apply on 'experiment'
[36m[2020-01-13 12:28:57 DEBUG] [__init__:72][39m Cleaning up controls
[36m[2020-01-13 12:28:57 DEBUG] [caching:42][39m Clearing activities cache
[36m[2020-01-13 12:29:00 DEBUG] [cli:70][39m ###############################################################################
[36m[2020-01-13 12:29:00 DEBUG] [cli:71][39m Running command 'run'
[36m[2020-01-13 12:29:00 DEBUG] [cli:75][39m Using settings file '/Users/john/.chaostoolkit/settings.yaml'
[36m[2020-01-13 12:29:01 DEBUG] [settings:24][39m The Chaos Toolkit settings file could not be found at '/Users/john/.chaostoolkit/settings.yaml'.
[36m[2020-01-13 12:29:01 DEBUG] [__init__:355][39m No controls to apply on 'loader'
[36m[2020-01-13 12:29:01 DEBUG] [__init__:355][39m No controls to apply on 'loader'
[36m[2020-01-13 12:29:01 DEBUG] [caching:25][39m Building activity cache...
[36m[2020-01-13 12:29:01 DEBUG] [caching:35][39m Cached 2 activities
[32m[2020-01-13 12:29:01 INFO] [experiment:54][39m Validating the experiment's syntax
[36m[2020-01-13 12:29:01 DEBUG] [configuration:36][39m Loading configuration...
[36m[2020-01-13 12:29:01 DEBUG] [secret:74][39m Loading secrets...
[36m[2020-01-13 12:29:01 DEBUG] [secret:89][39m Secrets loaded
[32m[2020-01-13 12:29:01 INFO] [experiment:100][39m Experiment looks valid
[36m[2020-01-13 12:29:01 DEBUG] [caching:42][39m Clearing activities cache
[36m[2020-01-13 12:29:01 DEBUG] [caching:25][39m Building activity cache...
[36m[2020-01-13 12:29:01 DEBUG] [caching:35][39m Cached 2 activities
[32m[2020-01-13 12:29:01 INFO] [experiment:179][39m Running experiment: Delay Movie Recommendation
[36m[2020-01-13 12:29:01 DEBUG] [configuration:36][39m Loading configuration...
[36m[2020-01-13 12:29:01 DEBUG] [secret:74][39m Loading secrets...
[36m[2020-01-13 12:29:01 DEBUG] [secret:89][39m Secrets loaded
[36m[2020-01-13 12:29:01 DEBUG] [__init__:39][39m Initializing controls
[36m[2020-01-13 12:29:01 DEBUG] [__init__:355][39m No controls to apply on 'experiment'
[32m[2020-01-13 12:29:01 INFO] [hypothesis:184][39m Steady state hypothesis: Movie recommendation in less than a second
[36m[2020-01-13 12:29:01 DEBUG] [__init__:355][39m No controls to apply on 'hypothesis'
[36m[2020-01-13 12:29:01 DEBUG] [__init__:355][39m No controls to apply on 'activity'
[32m[2020-01-13 12:29:01 INFO] [activity:158][39m Probe: we-can-request-sunset
[36m[2020-01-13 12:29:01 DEBUG] [activity:176][39m   => succeeded with '{'status': 200, 'headers': {'Content-Type': 'application/json', 'Transfer-Encoding': 'chunked', 'Date': 'Mon, 13 Jan 2020 11:29:00 GMT', 'Keep-Alive': 'timeout=60', 'Connection': 'keep-alive'}, 'body': {'title': 'Inception', 'duration': '2h 28m'}}'
[36m[2020-01-13 12:29:01 DEBUG] [__init__:355][39m No controls to apply on 'activity'
[36m[2020-01-13 12:29:01 DEBUG] [hypothesis:212][39m allowed tolerance is 200
[32m[2020-01-13 12:29:01 INFO] [hypothesis:222][39m Steady state hypothesis is met!
[36m[2020-01-13 12:29:01 DEBUG] [__init__:355][39m No controls to apply on 'hypothesis'
[36m[2020-01-13 12:29:01 DEBUG] [__init__:355][39m No controls to apply on 'method'
[36m[2020-01-13 12:29:01 DEBUG] [__init__:355][39m No controls to apply on 'activity'
[32m[2020-01-13 12:29:01 INFO] [activity:158][39m Action: enable_chaosmonkey
[36m[2020-01-13 12:29:01 DEBUG] [python:36][39m Activity 'enable_chaosmonkey' loaded from '/Users/john/.venvs/chaostk/lib/python3.7/site-packages/chaosspring/actions.py'
[36m[2020-01-13 12:29:01 DEBUG] [activity:176][39m   => succeeded with 'Chaos Monkey is enabled'
[36m[2020-01-13 12:29:01 DEBUG] [__init__:355][39m No controls to apply on 'activity'
[36m[2020-01-13 12:29:01 DEBUG] [__init__:355][39m No controls to apply on 'method'
[32m[2020-01-13 12:29:01 INFO] [hypothesis:184][39m Steady state hypothesis: Movie recommendation in less than a second
[36m[2020-01-13 12:29:01 DEBUG] [__init__:355][39m No controls to apply on 'hypothesis'
[36m[2020-01-13 12:29:01 DEBUG] [__init__:355][39m No controls to apply on 'activity'
[32m[2020-01-13 12:29:01 INFO] [activity:158][39m Probe: we-can-request-sunset
[36m[2020-01-13 12:29:01 DEBUG] [activity:230][39m Activity failed
    Traceback (most recent call last):
      File "/Users/john/.venvs/chaostk/lib/python3.7/site-packages/urllib3/connectionpool.py", line 421, in _make_request
        six.raise_from(e, None)
      File "<string>", line 3, in raise_from
      File "/Users/john/.venvs/chaostk/lib/python3.7/site-packages/urllib3/connectionpool.py", line 416, in _make_request
        httplib_response = conn.getresponse()
      File "/usr/local/Cellar/python/3.7.5/Frameworks/Python.framework/Versions/3.7/lib/python3.7/http/client.py", line 1344, in getresponse
        response.begin()
      File "/usr/local/Cellar/python/3.7.5/Frameworks/Python.framework/Versions/3.7/lib/python3.7/http/client.py", line 306, in begin
        version, status, reason = self._read_status()
      File "/usr/local/Cellar/python/3.7.5/Frameworks/Python.framework/Versions/3.7/lib/python3.7/http/client.py", line 267, in _read_status
        line = str(self.fp.readline(_MAXLINE + 1), "iso-8859-1")
      File "/usr/local/Cellar/python/3.7.5/Frameworks/Python.framework/Versions/3.7/lib/python3.7/socket.py", line 589, in readinto
        return self._sock.recv_into(b)
    socket.timeout: timed out
    
    During handling of the above exception, another exception occurred:
    
    Traceback (most recent call last):
      File "/Users/john/.venvs/chaostk/lib/python3.7/site-packages/requests/adapters.py", line 449, in send
        timeout=timeout
      File "/Users/john/.venvs/chaostk/lib/python3.7/site-packages/urllib3/connectionpool.py", line 720, in urlopen
        method, url, error=e, _pool=self, _stacktrace=sys.exc_info()[2]
      File "/Users/john/.venvs/chaostk/lib/python3.7/site-packages/urllib3/util/retry.py", line 400, in increment
        raise six.reraise(type(error), error, _stacktrace)
      File "/Users/john/.venvs/chaostk/lib/python3.7/site-packages/urllib3/packages/six.py", line 735, in reraise
        raise value
      File "/Users/john/.venvs/chaostk/lib/python3.7/site-packages/urllib3/connectionpool.py", line 672, in urlopen
        chunked=chunked,
      File "/Users/john/.venvs/chaostk/lib/python3.7/site-packages/urllib3/connectionpool.py", line 423, in _make_request
        self._raise_timeout(err=e, url=url, timeout_value=read_timeout)
      File "/Users/john/.venvs/chaostk/lib/python3.7/site-packages/urllib3/connectionpool.py", line 331, in _raise_timeout
        self, url, "Read timed out. (read timeout=%s)" % timeout_value
    urllib3.exceptions.ReadTimeoutError: HTTPConnectionPool(host='localhost', port=8080): Read timed out. (read timeout=0.1)
    
    During handling of the above exception, another exception occurred:
    
    Traceback (most recent call last):
      File "/Users/john/.venvs/chaostk/lib/python3.7/site-packages/chaoslib/provider/http.py", line 53, in run_http_activity
        verify=verify_tls)
      File "/Users/john/.venvs/chaostk/lib/python3.7/site-packages/requests/sessions.py", line 546, in get
        return self.request('GET', url, **kwargs)
      File "/Users/john/.venvs/chaostk/lib/python3.7/site-packages/requests/sessions.py", line 533, in request
        resp = self.send(prep, **send_kwargs)
      File "/Users/john/.venvs/chaostk/lib/python3.7/site-packages/requests/sessions.py", line 646, in send
        r = adapter.send(request, **kwargs)
      File "/Users/john/.venvs/chaostk/lib/python3.7/site-packages/requests/adapters.py", line 529, in send
        raise ReadTimeout(e, request=request)
    requests.exceptions.ReadTimeout: HTTPConnectionPool(host='localhost', port=8080): Read timed out. (read timeout=0.1)
    
    During handling of the above exception, another exception occurred:
    
    Traceback (most recent call last):
      File "/Users/john/.venvs/chaostk/lib/python3.7/site-packages/chaoslib/activity.py", line 227, in run_activity
        result = run_http_activity(activity, configuration, secrets)
      File "/Users/john/.venvs/chaostk/lib/python3.7/site-packages/chaoslib/provider/http.py", line 89, in run_http_activity
        raise ActivityFailed("activity took too long to complete")
    chaoslib.exceptions.ActivityFailed: activity took too long to complete
[31m[2020-01-13 12:29:01 ERROR] [activity:184][39m   => failed: activity took too long to complete
[36m[2020-01-13 12:29:01 DEBUG] [__init__:355][39m No controls to apply on 'activity'
[33m[2020-01-13 12:29:01 WARNING] [hypothesis:201][39m Probe terminated unexpectedly, so its tolerance could not be validated
[36m[2020-01-13 12:29:01 DEBUG] [__init__:355][39m No controls to apply on 'hypothesis'
[2020-01-13 12:29:01 CRITICAL] [experiment:241] Steady state probe 'we-can-request-sunset' is not in the given tolerance so failing this experiment
[32m[2020-01-13 12:29:01 INFO] [experiment:320][39m Let's rollback...
[36m[2020-01-13 12:29:01 DEBUG] [__init__:355][39m No controls to apply on 'rollback'
[32m[2020-01-13 12:29:01 INFO] [rollback:28][39m Rollback: disable_chaosmonkey
[36m[2020-01-13 12:29:01 DEBUG] [__init__:355][39m No controls to apply on 'activity'
[32m[2020-01-13 12:29:01 INFO] [activity:158][39m Action: disable_chaosmonkey
[36m[2020-01-13 12:29:01 DEBUG] [python:36][39m Activity 'disable_chaosmonkey' loaded from '/Users/john/.venvs/chaostk/lib/python3.7/site-packages/chaosspring/actions.py'
[36m[2020-01-13 12:29:01 DEBUG] [activity:176][39m   => succeeded with 'Chaos Monkey is disabled'
[36m[2020-01-13 12:29:01 DEBUG] [__init__:355][39m No controls to apply on 'activity'
[36m[2020-01-13 12:29:01 DEBUG] [__init__:355][39m No controls to apply on 'rollback'
[32m[2020-01-13 12:29:01 INFO] [experiment:270][39m Experiment ended with status: deviated
[32m[2020-01-13 12:29:01 INFO] [experiment:274][39m The steady-state has deviated, a weakness may have been discovered
[36m[2020-01-13 12:29:01 DEBUG] [__init__:355][39m No controls to apply on 'experiment'
[36m[2020-01-13 12:29:01 DEBUG] [__init__:72][39m Cleaning up controls
[36m[2020-01-13 12:29:01 DEBUG] [caching:42][39m Clearing activities cache
[36m[2020-01-13 12:29:15 DEBUG] [cli:70][39m ###############################################################################
[36m[2020-01-13 12:29:15 DEBUG] [cli:71][39m Running command 'run'
[36m[2020-01-13 12:29:15 DEBUG] [cli:75][39m Using settings file '/Users/john/.chaostoolkit/settings.yaml'
[36m[2020-01-13 12:29:16 DEBUG] [settings:24][39m The Chaos Toolkit settings file could not be found at '/Users/john/.chaostoolkit/settings.yaml'.
[36m[2020-01-13 12:29:16 DEBUG] [__init__:355][39m No controls to apply on 'loader'
[36m[2020-01-13 12:29:16 DEBUG] [__init__:355][39m No controls to apply on 'loader'
[36m[2020-01-13 12:29:16 DEBUG] [caching:25][39m Building activity cache...
[36m[2020-01-13 12:29:16 DEBUG] [caching:35][39m Cached 2 activities
[32m[2020-01-13 12:29:16 INFO] [experiment:54][39m Validating the experiment's syntax
[36m[2020-01-13 12:29:16 DEBUG] [configuration:36][39m Loading configuration...
[36m[2020-01-13 12:29:16 DEBUG] [secret:74][39m Loading secrets...
[36m[2020-01-13 12:29:16 DEBUG] [secret:89][39m Secrets loaded
[32m[2020-01-13 12:29:16 INFO] [experiment:100][39m Experiment looks valid
[36m[2020-01-13 12:29:16 DEBUG] [caching:42][39m Clearing activities cache
[36m[2020-01-13 12:29:16 DEBUG] [caching:25][39m Building activity cache...
[36m[2020-01-13 12:29:16 DEBUG] [caching:35][39m Cached 2 activities
[32m[2020-01-13 12:29:16 INFO] [experiment:179][39m Running experiment: Delay Movie Recommendation
[36m[2020-01-13 12:29:16 DEBUG] [configuration:36][39m Loading configuration...
[36m[2020-01-13 12:29:16 DEBUG] [secret:74][39m Loading secrets...
[36m[2020-01-13 12:29:16 DEBUG] [secret:89][39m Secrets loaded
[36m[2020-01-13 12:29:16 DEBUG] [__init__:39][39m Initializing controls
[36m[2020-01-13 12:29:16 DEBUG] [__init__:355][39m No controls to apply on 'experiment'
[32m[2020-01-13 12:29:16 INFO] [hypothesis:184][39m Steady state hypothesis: Movie recommendation in less than a second
[36m[2020-01-13 12:29:16 DEBUG] [__init__:355][39m No controls to apply on 'hypothesis'
[36m[2020-01-13 12:29:16 DEBUG] [__init__:355][39m No controls to apply on 'activity'
[32m[2020-01-13 12:29:16 INFO] [activity:158][39m Probe: we-can-request-sunset
[36m[2020-01-13 12:29:16 DEBUG] [activity:230][39m Activity failed
    Traceback (most recent call last):
      File "/Users/john/.venvs/chaostk/lib/python3.7/site-packages/urllib3/connectionpool.py", line 421, in _make_request
        six.raise_from(e, None)
      File "<string>", line 3, in raise_from
      File "/Users/john/.venvs/chaostk/lib/python3.7/site-packages/urllib3/connectionpool.py", line 416, in _make_request
        httplib_response = conn.getresponse()
      File "/usr/local/Cellar/python/3.7.5/Frameworks/Python.framework/Versions/3.7/lib/python3.7/http/client.py", line 1344, in getresponse
        response.begin()
      File "/usr/local/Cellar/python/3.7.5/Frameworks/Python.framework/Versions/3.7/lib/python3.7/http/client.py", line 306, in begin
        version, status, reason = self._read_status()
      File "/usr/local/Cellar/python/3.7.5/Frameworks/Python.framework/Versions/3.7/lib/python3.7/http/client.py", line 267, in _read_status
        line = str(self.fp.readline(_MAXLINE + 1), "iso-8859-1")
      File "/usr/local/Cellar/python/3.7.5/Frameworks/Python.framework/Versions/3.7/lib/python3.7/socket.py", line 589, in readinto
        return self._sock.recv_into(b)
    socket.timeout: timed out
    
    During handling of the above exception, another exception occurred:
    
    Traceback (most recent call last):
      File "/Users/john/.venvs/chaostk/lib/python3.7/site-packages/requests/adapters.py", line 449, in send
        timeout=timeout
      File "/Users/john/.venvs/chaostk/lib/python3.7/site-packages/urllib3/connectionpool.py", line 720, in urlopen
        method, url, error=e, _pool=self, _stacktrace=sys.exc_info()[2]
      File "/Users/john/.venvs/chaostk/lib/python3.7/site-packages/urllib3/util/retry.py", line 400, in increment
        raise six.reraise(type(error), error, _stacktrace)
      File "/Users/john/.venvs/chaostk/lib/python3.7/site-packages/urllib3/packages/six.py", line 735, in reraise
        raise value
      File "/Users/john/.venvs/chaostk/lib/python3.7/site-packages/urllib3/connectionpool.py", line 672, in urlopen
        chunked=chunked,
      File "/Users/john/.venvs/chaostk/lib/python3.7/site-packages/urllib3/connectionpool.py", line 423, in _make_request
        self._raise_timeout(err=e, url=url, timeout_value=read_timeout)
      File "/Users/john/.venvs/chaostk/lib/python3.7/site-packages/urllib3/connectionpool.py", line 331, in _raise_timeout
        self, url, "Read timed out. (read timeout=%s)" % timeout_value
    urllib3.exceptions.ReadTimeoutError: HTTPConnectionPool(host='localhost', port=8080): Read timed out. (read timeout=0.001)
    
    During handling of the above exception, another exception occurred:
    
    Traceback (most recent call last):
      File "/Users/john/.venvs/chaostk/lib/python3.7/site-packages/chaoslib/provider/http.py", line 53, in run_http_activity
        verify=verify_tls)
      File "/Users/john/.venvs/chaostk/lib/python3.7/site-packages/requests/sessions.py", line 546, in get
        return self.request('GET', url, **kwargs)
      File "/Users/john/.venvs/chaostk/lib/python3.7/site-packages/requests/sessions.py", line 533, in request
        resp = self.send(prep, **send_kwargs)
      File "/Users/john/.venvs/chaostk/lib/python3.7/site-packages/requests/sessions.py", line 646, in send
        r = adapter.send(request, **kwargs)
      File "/Users/john/.venvs/chaostk/lib/python3.7/site-packages/requests/adapters.py", line 529, in send
        raise ReadTimeout(e, request=request)
    requests.exceptions.ReadTimeout: HTTPConnectionPool(host='localhost', port=8080): Read timed out. (read timeout=0.001)
    
    During handling of the above exception, another exception occurred:
    
    Traceback (most recent call last):
      File "/Users/john/.venvs/chaostk/lib/python3.7/site-packages/chaoslib/activity.py", line 227, in run_activity
        result = run_http_activity(activity, configuration, secrets)
      File "/Users/john/.venvs/chaostk/lib/python3.7/site-packages/chaoslib/provider/http.py", line 89, in run_http_activity
        raise ActivityFailed("activity took too long to complete")
    chaoslib.exceptions.ActivityFailed: activity took too long to complete
[31m[2020-01-13 12:29:16 ERROR] [activity:184][39m   => failed: activity took too long to complete
[36m[2020-01-13 12:29:16 DEBUG] [__init__:355][39m No controls to apply on 'activity'
[33m[2020-01-13 12:29:16 WARNING] [hypothesis:201][39m Probe terminated unexpectedly, so its tolerance could not be validated
[36m[2020-01-13 12:29:16 DEBUG] [__init__:355][39m No controls to apply on 'hypothesis'
[2020-01-13 12:29:16 CRITICAL] [experiment:215] Steady state probe 'we-can-request-sunset' is not in the given tolerance so failing this experiment
[32m[2020-01-13 12:29:16 INFO] [experiment:320][39m Let's rollback...
[36m[2020-01-13 12:29:16 DEBUG] [__init__:355][39m No controls to apply on 'rollback'
[32m[2020-01-13 12:29:16 INFO] [rollback:28][39m Rollback: disable_chaosmonkey
[36m[2020-01-13 12:29:16 DEBUG] [__init__:355][39m No controls to apply on 'activity'
[32m[2020-01-13 12:29:16 INFO] [activity:158][39m Action: disable_chaosmonkey
[36m[2020-01-13 12:29:16 DEBUG] [python:36][39m Activity 'disable_chaosmonkey' loaded from '/Users/john/.venvs/chaostk/lib/python3.7/site-packages/chaosspring/actions.py'
[36m[2020-01-13 12:29:16 DEBUG] [activity:176][39m   => succeeded with 'Chaos Monkey is disabled'
[36m[2020-01-13 12:29:16 DEBUG] [__init__:355][39m No controls to apply on 'activity'
[36m[2020-01-13 12:29:16 DEBUG] [__init__:355][39m No controls to apply on 'rollback'
[32m[2020-01-13 12:29:16 INFO] [experiment:270][39m Experiment ended with status: failed
[36m[2020-01-13 12:29:16 DEBUG] [__init__:355][39m No controls to apply on 'experiment'
[36m[2020-01-13 12:29:16 DEBUG] [__init__:72][39m Cleaning up controls
[36m[2020-01-13 12:29:16 DEBUG] [caching:42][39m Clearing activities cache
[36m[2020-01-13 12:29:29 DEBUG] [cli:70][39m ###############################################################################
[36m[2020-01-13 12:29:29 DEBUG] [cli:71][39m Running command 'run'
[36m[2020-01-13 12:29:29 DEBUG] [cli:75][39m Using settings file '/Users/john/.chaostoolkit/settings.yaml'
[36m[2020-01-13 12:29:30 DEBUG] [settings:24][39m The Chaos Toolkit settings file could not be found at '/Users/john/.chaostoolkit/settings.yaml'.
[36m[2020-01-13 12:29:30 DEBUG] [__init__:355][39m No controls to apply on 'loader'
[36m[2020-01-13 12:29:30 DEBUG] [__init__:355][39m No controls to apply on 'loader'
[36m[2020-01-13 12:29:30 DEBUG] [caching:25][39m Building activity cache...
[36m[2020-01-13 12:29:30 DEBUG] [caching:35][39m Cached 2 activities
[32m[2020-01-13 12:29:30 INFO] [experiment:54][39m Validating the experiment's syntax
[36m[2020-01-13 12:29:30 DEBUG] [configuration:36][39m Loading configuration...
[36m[2020-01-13 12:29:30 DEBUG] [secret:74][39m Loading secrets...
[36m[2020-01-13 12:29:30 DEBUG] [secret:89][39m Secrets loaded
[32m[2020-01-13 12:29:30 INFO] [experiment:100][39m Experiment looks valid
[36m[2020-01-13 12:29:30 DEBUG] [caching:42][39m Clearing activities cache
[36m[2020-01-13 12:29:30 DEBUG] [caching:25][39m Building activity cache...
[36m[2020-01-13 12:29:30 DEBUG] [caching:35][39m Cached 2 activities
[32m[2020-01-13 12:29:30 INFO] [experiment:179][39m Running experiment: Delay Movie Recommendation
[36m[2020-01-13 12:29:30 DEBUG] [configuration:36][39m Loading configuration...
[36m[2020-01-13 12:29:30 DEBUG] [secret:74][39m Loading secrets...
[36m[2020-01-13 12:29:30 DEBUG] [secret:89][39m Secrets loaded
[36m[2020-01-13 12:29:30 DEBUG] [__init__:39][39m Initializing controls
[36m[2020-01-13 12:29:30 DEBUG] [__init__:355][39m No controls to apply on 'experiment'
[32m[2020-01-13 12:29:30 INFO] [hypothesis:184][39m Steady state hypothesis: Movie recommendation in less than a second
[36m[2020-01-13 12:29:30 DEBUG] [__init__:355][39m No controls to apply on 'hypothesis'
[36m[2020-01-13 12:29:30 DEBUG] [__init__:355][39m No controls to apply on 'activity'
[32m[2020-01-13 12:29:30 INFO] [activity:158][39m Probe: we-can-request-sunset
[36m[2020-01-13 12:29:30 DEBUG] [activity:230][39m Activity failed
    Traceback (most recent call last):
      File "/Users/john/.venvs/chaostk/lib/python3.7/site-packages/urllib3/connectionpool.py", line 421, in _make_request
        six.raise_from(e, None)
      File "<string>", line 3, in raise_from
      File "/Users/john/.venvs/chaostk/lib/python3.7/site-packages/urllib3/connectionpool.py", line 416, in _make_request
        httplib_response = conn.getresponse()
      File "/usr/local/Cellar/python/3.7.5/Frameworks/Python.framework/Versions/3.7/lib/python3.7/http/client.py", line 1344, in getresponse
        response.begin()
      File "/usr/local/Cellar/python/3.7.5/Frameworks/Python.framework/Versions/3.7/lib/python3.7/http/client.py", line 306, in begin
        version, status, reason = self._read_status()
      File "/usr/local/Cellar/python/3.7.5/Frameworks/Python.framework/Versions/3.7/lib/python3.7/http/client.py", line 267, in _read_status
        line = str(self.fp.readline(_MAXLINE + 1), "iso-8859-1")
      File "/usr/local/Cellar/python/3.7.5/Frameworks/Python.framework/Versions/3.7/lib/python3.7/socket.py", line 589, in readinto
        return self._sock.recv_into(b)
    socket.timeout: timed out
    
    During handling of the above exception, another exception occurred:
    
    Traceback (most recent call last):
      File "/Users/john/.venvs/chaostk/lib/python3.7/site-packages/requests/adapters.py", line 449, in send
        timeout=timeout
      File "/Users/john/.venvs/chaostk/lib/python3.7/site-packages/urllib3/connectionpool.py", line 720, in urlopen
        method, url, error=e, _pool=self, _stacktrace=sys.exc_info()[2]
      File "/Users/john/.venvs/chaostk/lib/python3.7/site-packages/urllib3/util/retry.py", line 400, in increment
        raise six.reraise(type(error), error, _stacktrace)
      File "/Users/john/.venvs/chaostk/lib/python3.7/site-packages/urllib3/packages/six.py", line 735, in reraise
        raise value
      File "/Users/john/.venvs/chaostk/lib/python3.7/site-packages/urllib3/connectionpool.py", line 672, in urlopen
        chunked=chunked,
      File "/Users/john/.venvs/chaostk/lib/python3.7/site-packages/urllib3/connectionpool.py", line 423, in _make_request
        self._raise_timeout(err=e, url=url, timeout_value=read_timeout)
      File "/Users/john/.venvs/chaostk/lib/python3.7/site-packages/urllib3/connectionpool.py", line 331, in _raise_timeout
        self, url, "Read timed out. (read timeout=%s)" % timeout_value
    urllib3.exceptions.ReadTimeoutError: HTTPConnectionPool(host='localhost', port=8080): Read timed out. (read timeout=0.001)
    
    During handling of the above exception, another exception occurred:
    
    Traceback (most recent call last):
      File "/Users/john/.venvs/chaostk/lib/python3.7/site-packages/chaoslib/provider/http.py", line 53, in run_http_activity
        verify=verify_tls)
      File "/Users/john/.venvs/chaostk/lib/python3.7/site-packages/requests/sessions.py", line 546, in get
        return self.request('GET', url, **kwargs)
      File "/Users/john/.venvs/chaostk/lib/python3.7/site-packages/requests/sessions.py", line 533, in request
        resp = self.send(prep, **send_kwargs)
      File "/Users/john/.venvs/chaostk/lib/python3.7/site-packages/requests/sessions.py", line 646, in send
        r = adapter.send(request, **kwargs)
      File "/Users/john/.venvs/chaostk/lib/python3.7/site-packages/requests/adapters.py", line 529, in send
        raise ReadTimeout(e, request=request)
    requests.exceptions.ReadTimeout: HTTPConnectionPool(host='localhost', port=8080): Read timed out. (read timeout=0.001)
    
    During handling of the above exception, another exception occurred:
    
    Traceback (most recent call last):
      File "/Users/john/.venvs/chaostk/lib/python3.7/site-packages/chaoslib/activity.py", line 227, in run_activity
        result = run_http_activity(activity, configuration, secrets)
      File "/Users/john/.venvs/chaostk/lib/python3.7/site-packages/chaoslib/provider/http.py", line 89, in run_http_activity
        raise ActivityFailed("activity took too long to complete")
    chaoslib.exceptions.ActivityFailed: activity took too long to complete
[31m[2020-01-13 12:29:30 ERROR] [activity:184][39m   => failed: activity took too long to complete
[36m[2020-01-13 12:29:30 DEBUG] [__init__:355][39m No controls to apply on 'activity'
[33m[2020-01-13 12:29:30 WARNING] [hypothesis:201][39m Probe terminated unexpectedly, so its tolerance could not be validated
[36m[2020-01-13 12:29:30 DEBUG] [__init__:355][39m No controls to apply on 'hypothesis'
[2020-01-13 12:29:30 CRITICAL] [experiment:215] Steady state probe 'we-can-request-sunset' is not in the given tolerance so failing this experiment
[32m[2020-01-13 12:29:30 INFO] [experiment:320][39m Let's rollback...
[36m[2020-01-13 12:29:30 DEBUG] [__init__:355][39m No controls to apply on 'rollback'
[32m[2020-01-13 12:29:30 INFO] [rollback:28][39m Rollback: disable_chaosmonkey
[36m[2020-01-13 12:29:30 DEBUG] [__init__:355][39m No controls to apply on 'activity'
[32m[2020-01-13 12:29:30 INFO] [activity:158][39m Action: disable_chaosmonkey
[36m[2020-01-13 12:29:30 DEBUG] [python:36][39m Activity 'disable_chaosmonkey' loaded from '/Users/john/.venvs/chaostk/lib/python3.7/site-packages/chaosspring/actions.py'
[36m[2020-01-13 12:29:30 DEBUG] [activity:176][39m   => succeeded with 'Chaos Monkey is disabled'
[36m[2020-01-13 12:29:30 DEBUG] [__init__:355][39m No controls to apply on 'activity'
[36m[2020-01-13 12:29:30 DEBUG] [__init__:355][39m No controls to apply on 'rollback'
[32m[2020-01-13 12:29:30 INFO] [experiment:270][39m Experiment ended with status: failed
[36m[2020-01-13 12:29:30 DEBUG] [__init__:355][39m No controls to apply on 'experiment'
[36m[2020-01-13 12:29:30 DEBUG] [__init__:72][39m Cleaning up controls
[36m[2020-01-13 12:29:30 DEBUG] [caching:42][39m Clearing activities cache
[36m[2020-01-13 12:29:37 DEBUG] [cli:70][39m ###############################################################################
[36m[2020-01-13 12:29:37 DEBUG] [cli:71][39m Running command 'run'
[36m[2020-01-13 12:29:37 DEBUG] [cli:75][39m Using settings file '/Users/john/.chaostoolkit/settings.yaml'
[36m[2020-01-13 12:29:37 DEBUG] [settings:24][39m The Chaos Toolkit settings file could not be found at '/Users/john/.chaostoolkit/settings.yaml'.
[36m[2020-01-13 12:29:37 DEBUG] [__init__:355][39m No controls to apply on 'loader'
[36m[2020-01-13 12:29:37 DEBUG] [__init__:355][39m No controls to apply on 'loader'
[36m[2020-01-13 12:29:37 DEBUG] [caching:25][39m Building activity cache...
[36m[2020-01-13 12:29:37 DEBUG] [caching:35][39m Cached 2 activities
[32m[2020-01-13 12:29:37 INFO] [experiment:54][39m Validating the experiment's syntax
[36m[2020-01-13 12:29:37 DEBUG] [configuration:36][39m Loading configuration...
[36m[2020-01-13 12:29:37 DEBUG] [secret:74][39m Loading secrets...
[36m[2020-01-13 12:29:37 DEBUG] [secret:89][39m Secrets loaded
[32m[2020-01-13 12:29:37 INFO] [experiment:100][39m Experiment looks valid
[36m[2020-01-13 12:29:37 DEBUG] [caching:42][39m Clearing activities cache
[36m[2020-01-13 12:29:37 DEBUG] [caching:25][39m Building activity cache...
[36m[2020-01-13 12:29:37 DEBUG] [caching:35][39m Cached 2 activities
[32m[2020-01-13 12:29:37 INFO] [experiment:179][39m Running experiment: Delay Movie Recommendation
[36m[2020-01-13 12:29:37 DEBUG] [configuration:36][39m Loading configuration...
[36m[2020-01-13 12:29:37 DEBUG] [secret:74][39m Loading secrets...
[36m[2020-01-13 12:29:37 DEBUG] [secret:89][39m Secrets loaded
[36m[2020-01-13 12:29:37 DEBUG] [__init__:39][39m Initializing controls
[36m[2020-01-13 12:29:37 DEBUG] [__init__:355][39m No controls to apply on 'experiment'
[32m[2020-01-13 12:29:37 INFO] [hypothesis:184][39m Steady state hypothesis: Movie recommendation in less than a second
[36m[2020-01-13 12:29:37 DEBUG] [__init__:355][39m No controls to apply on 'hypothesis'
[36m[2020-01-13 12:29:37 DEBUG] [__init__:355][39m No controls to apply on 'activity'
[32m[2020-01-13 12:29:37 INFO] [activity:158][39m Probe: we-can-request-sunset
[36m[2020-01-13 12:29:37 DEBUG] [activity:176][39m   => succeeded with '{'status': 200, 'headers': {'Content-Type': 'application/json', 'Transfer-Encoding': 'chunked', 'Date': 'Mon, 13 Jan 2020 11:29:37 GMT', 'Keep-Alive': 'timeout=60', 'Connection': 'keep-alive'}, 'body': {'title': 'Inception', 'duration': '2h 28m'}}'
[36m[2020-01-13 12:29:37 DEBUG] [__init__:355][39m No controls to apply on 'activity'
[36m[2020-01-13 12:29:37 DEBUG] [hypothesis:212][39m allowed tolerance is 200
[32m[2020-01-13 12:29:37 INFO] [hypothesis:222][39m Steady state hypothesis is met!
[36m[2020-01-13 12:29:37 DEBUG] [__init__:355][39m No controls to apply on 'hypothesis'
[36m[2020-01-13 12:29:37 DEBUG] [__init__:355][39m No controls to apply on 'method'
[36m[2020-01-13 12:29:37 DEBUG] [__init__:355][39m No controls to apply on 'activity'
[32m[2020-01-13 12:29:37 INFO] [activity:158][39m Action: enable_chaosmonkey
[36m[2020-01-13 12:29:37 DEBUG] [python:36][39m Activity 'enable_chaosmonkey' loaded from '/Users/john/.venvs/chaostk/lib/python3.7/site-packages/chaosspring/actions.py'
[36m[2020-01-13 12:29:37 DEBUG] [activity:176][39m   => succeeded with 'Chaos Monkey is enabled'
[36m[2020-01-13 12:29:37 DEBUG] [__init__:355][39m No controls to apply on 'activity'
[36m[2020-01-13 12:29:37 DEBUG] [__init__:355][39m No controls to apply on 'method'
[32m[2020-01-13 12:29:37 INFO] [hypothesis:184][39m Steady state hypothesis: Movie recommendation in less than a second
[36m[2020-01-13 12:29:37 DEBUG] [__init__:355][39m No controls to apply on 'hypothesis'
[36m[2020-01-13 12:29:37 DEBUG] [__init__:355][39m No controls to apply on 'activity'
[32m[2020-01-13 12:29:37 INFO] [activity:158][39m Probe: we-can-request-sunset
[36m[2020-01-13 12:29:38 DEBUG] [activity:230][39m Activity failed
    Traceback (most recent call last):
      File "/Users/john/.venvs/chaostk/lib/python3.7/site-packages/urllib3/connectionpool.py", line 421, in _make_request
        six.raise_from(e, None)
      File "<string>", line 3, in raise_from
      File "/Users/john/.venvs/chaostk/lib/python3.7/site-packages/urllib3/connectionpool.py", line 416, in _make_request
        httplib_response = conn.getresponse()
      File "/usr/local/Cellar/python/3.7.5/Frameworks/Python.framework/Versions/3.7/lib/python3.7/http/client.py", line 1344, in getresponse
        response.begin()
      File "/usr/local/Cellar/python/3.7.5/Frameworks/Python.framework/Versions/3.7/lib/python3.7/http/client.py", line 306, in begin
        version, status, reason = self._read_status()
      File "/usr/local/Cellar/python/3.7.5/Frameworks/Python.framework/Versions/3.7/lib/python3.7/http/client.py", line 267, in _read_status
        line = str(self.fp.readline(_MAXLINE + 1), "iso-8859-1")
      File "/usr/local/Cellar/python/3.7.5/Frameworks/Python.framework/Versions/3.7/lib/python3.7/socket.py", line 589, in readinto
        return self._sock.recv_into(b)
    socket.timeout: timed out
    
    During handling of the above exception, another exception occurred:
    
    Traceback (most recent call last):
      File "/Users/john/.venvs/chaostk/lib/python3.7/site-packages/requests/adapters.py", line 449, in send
        timeout=timeout
      File "/Users/john/.venvs/chaostk/lib/python3.7/site-packages/urllib3/connectionpool.py", line 720, in urlopen
        method, url, error=e, _pool=self, _stacktrace=sys.exc_info()[2]
      File "/Users/john/.venvs/chaostk/lib/python3.7/site-packages/urllib3/util/retry.py", line 400, in increment
        raise six.reraise(type(error), error, _stacktrace)
      File "/Users/john/.venvs/chaostk/lib/python3.7/site-packages/urllib3/packages/six.py", line 735, in reraise
        raise value
      File "/Users/john/.venvs/chaostk/lib/python3.7/site-packages/urllib3/connectionpool.py", line 672, in urlopen
        chunked=chunked,
      File "/Users/john/.venvs/chaostk/lib/python3.7/site-packages/urllib3/connectionpool.py", line 423, in _make_request
        self._raise_timeout(err=e, url=url, timeout_value=read_timeout)
      File "/Users/john/.venvs/chaostk/lib/python3.7/site-packages/urllib3/connectionpool.py", line 331, in _raise_timeout
        self, url, "Read timed out. (read timeout=%s)" % timeout_value
    urllib3.exceptions.ReadTimeoutError: HTTPConnectionPool(host='localhost', port=8080): Read timed out. (read timeout=1)
    
    During handling of the above exception, another exception occurred:
    
    Traceback (most recent call last):
      File "/Users/john/.venvs/chaostk/lib/python3.7/site-packages/chaoslib/provider/http.py", line 53, in run_http_activity
        verify=verify_tls)
      File "/Users/john/.venvs/chaostk/lib/python3.7/site-packages/requests/sessions.py", line 546, in get
        return self.request('GET', url, **kwargs)
      File "/Users/john/.venvs/chaostk/lib/python3.7/site-packages/requests/sessions.py", line 533, in request
        resp = self.send(prep, **send_kwargs)
      File "/Users/john/.venvs/chaostk/lib/python3.7/site-packages/requests/sessions.py", line 646, in send
        r = adapter.send(request, **kwargs)
      File "/Users/john/.venvs/chaostk/lib/python3.7/site-packages/requests/adapters.py", line 529, in send
        raise ReadTimeout(e, request=request)
    requests.exceptions.ReadTimeout: HTTPConnectionPool(host='localhost', port=8080): Read timed out. (read timeout=1)
    
    During handling of the above exception, another exception occurred:
    
    Traceback (most recent call last):
      File "/Users/john/.venvs/chaostk/lib/python3.7/site-packages/chaoslib/activity.py", line 227, in run_activity
        result = run_http_activity(activity, configuration, secrets)
      File "/Users/john/.venvs/chaostk/lib/python3.7/site-packages/chaoslib/provider/http.py", line 89, in run_http_activity
        raise ActivityFailed("activity took too long to complete")
    chaoslib.exceptions.ActivityFailed: activity took too long to complete
[31m[2020-01-13 12:29:38 ERROR] [activity:184][39m   => failed: activity took too long to complete
[36m[2020-01-13 12:29:38 DEBUG] [__init__:355][39m No controls to apply on 'activity'
[33m[2020-01-13 12:29:38 WARNING] [hypothesis:201][39m Probe terminated unexpectedly, so its tolerance could not be validated
[36m[2020-01-13 12:29:38 DEBUG] [__init__:355][39m No controls to apply on 'hypothesis'
[2020-01-13 12:29:38 CRITICAL] [experiment:241] Steady state probe 'we-can-request-sunset' is not in the given tolerance so failing this experiment
[32m[2020-01-13 12:29:38 INFO] [experiment:320][39m Let's rollback...
[36m[2020-01-13 12:29:38 DEBUG] [__init__:355][39m No controls to apply on 'rollback'
[32m[2020-01-13 12:29:38 INFO] [rollback:28][39m Rollback: disable_chaosmonkey
[36m[2020-01-13 12:29:38 DEBUG] [__init__:355][39m No controls to apply on 'activity'
[32m[2020-01-13 12:29:38 INFO] [activity:158][39m Action: disable_chaosmonkey
[36m[2020-01-13 12:29:38 DEBUG] [python:36][39m Activity 'disable_chaosmonkey' loaded from '/Users/john/.venvs/chaostk/lib/python3.7/site-packages/chaosspring/actions.py'
[36m[2020-01-13 12:29:38 DEBUG] [activity:176][39m   => succeeded with 'Chaos Monkey is disabled'
[36m[2020-01-13 12:29:38 DEBUG] [__init__:355][39m No controls to apply on 'activity'
[36m[2020-01-13 12:29:38 DEBUG] [__init__:355][39m No controls to apply on 'rollback'
[32m[2020-01-13 12:29:38 INFO] [experiment:270][39m Experiment ended with status: deviated
[32m[2020-01-13 12:29:38 INFO] [experiment:274][39m The steady-state has deviated, a weakness may have been discovered
[36m[2020-01-13 12:29:38 DEBUG] [__init__:355][39m No controls to apply on 'experiment'
[36m[2020-01-13 12:29:38 DEBUG] [__init__:72][39m Cleaning up controls
[36m[2020-01-13 12:29:38 DEBUG] [caching:42][39m Clearing activities cache
[36m[2020-01-13 12:30:15 DEBUG] [cli:70][39m ###############################################################################
[36m[2020-01-13 12:30:15 DEBUG] [cli:71][39m Running command 'run'
[36m[2020-01-13 12:30:15 DEBUG] [cli:75][39m Using settings file '/Users/john/.chaostoolkit/settings.yaml'
[36m[2020-01-13 12:30:15 DEBUG] [settings:24][39m The Chaos Toolkit settings file could not be found at '/Users/john/.chaostoolkit/settings.yaml'.
[36m[2020-01-13 12:30:15 DEBUG] [__init__:355][39m No controls to apply on 'loader'
[36m[2020-01-13 12:30:15 DEBUG] [__init__:355][39m No controls to apply on 'loader'
[36m[2020-01-13 12:30:15 DEBUG] [caching:25][39m Building activity cache...
[36m[2020-01-13 12:30:15 DEBUG] [caching:35][39m Cached 2 activities
[32m[2020-01-13 12:30:15 INFO] [experiment:54][39m Validating the experiment's syntax
[36m[2020-01-13 12:30:15 DEBUG] [configuration:36][39m Loading configuration...
[36m[2020-01-13 12:30:15 DEBUG] [secret:74][39m Loading secrets...
[36m[2020-01-13 12:30:15 DEBUG] [secret:89][39m Secrets loaded
[32m[2020-01-13 12:30:15 INFO] [experiment:100][39m Experiment looks valid
[36m[2020-01-13 12:30:15 DEBUG] [caching:42][39m Clearing activities cache
[36m[2020-01-13 12:30:15 DEBUG] [caching:25][39m Building activity cache...
[36m[2020-01-13 12:30:15 DEBUG] [caching:35][39m Cached 2 activities
[32m[2020-01-13 12:30:15 INFO] [experiment:179][39m Running experiment: Delay Movie Recommendation
[36m[2020-01-13 12:30:15 DEBUG] [configuration:36][39m Loading configuration...
[36m[2020-01-13 12:30:15 DEBUG] [secret:74][39m Loading secrets...
[36m[2020-01-13 12:30:15 DEBUG] [secret:89][39m Secrets loaded
[36m[2020-01-13 12:30:15 DEBUG] [__init__:39][39m Initializing controls
[36m[2020-01-13 12:30:15 DEBUG] [__init__:355][39m No controls to apply on 'experiment'
[32m[2020-01-13 12:30:15 INFO] [hypothesis:184][39m Steady state hypothesis: Movie recommendation in less than a second
[36m[2020-01-13 12:30:15 DEBUG] [__init__:355][39m No controls to apply on 'hypothesis'
[36m[2020-01-13 12:30:15 DEBUG] [__init__:355][39m No controls to apply on 'activity'
[32m[2020-01-13 12:30:15 INFO] [activity:158][39m Probe: we-can-request-movie
[36m[2020-01-13 12:30:15 DEBUG] [activity:176][39m   => succeeded with '{'status': 200, 'headers': {'Content-Type': 'application/json', 'Transfer-Encoding': 'chunked', 'Date': 'Mon, 13 Jan 2020 11:30:15 GMT', 'Keep-Alive': 'timeout=60', 'Connection': 'keep-alive'}, 'body': {'title': 'Inception', 'duration': '2h 28m'}}'
[36m[2020-01-13 12:30:15 DEBUG] [__init__:355][39m No controls to apply on 'activity'
[36m[2020-01-13 12:30:15 DEBUG] [hypothesis:212][39m allowed tolerance is 200
[32m[2020-01-13 12:30:15 INFO] [hypothesis:222][39m Steady state hypothesis is met!
[36m[2020-01-13 12:30:15 DEBUG] [__init__:355][39m No controls to apply on 'hypothesis'
[36m[2020-01-13 12:30:15 DEBUG] [__init__:355][39m No controls to apply on 'method'
[36m[2020-01-13 12:30:15 DEBUG] [__init__:355][39m No controls to apply on 'activity'
[32m[2020-01-13 12:30:15 INFO] [activity:158][39m Action: enable_chaosmonkey
[36m[2020-01-13 12:30:15 DEBUG] [python:36][39m Activity 'enable_chaosmonkey' loaded from '/Users/john/.venvs/chaostk/lib/python3.7/site-packages/chaosspring/actions.py'
[36m[2020-01-13 12:30:15 DEBUG] [activity:176][39m   => succeeded with 'Chaos Monkey is enabled'
[36m[2020-01-13 12:30:15 DEBUG] [__init__:355][39m No controls to apply on 'activity'
[36m[2020-01-13 12:30:15 DEBUG] [__init__:355][39m No controls to apply on 'method'
[32m[2020-01-13 12:30:15 INFO] [hypothesis:184][39m Steady state hypothesis: Movie recommendation in less than a second
[36m[2020-01-13 12:30:15 DEBUG] [__init__:355][39m No controls to apply on 'hypothesis'
[36m[2020-01-13 12:30:15 DEBUG] [__init__:355][39m No controls to apply on 'activity'
[32m[2020-01-13 12:30:15 INFO] [activity:158][39m Probe: we-can-request-movie
[36m[2020-01-13 12:30:16 DEBUG] [activity:230][39m Activity failed
    Traceback (most recent call last):
      File "/Users/john/.venvs/chaostk/lib/python3.7/site-packages/urllib3/connectionpool.py", line 421, in _make_request
        six.raise_from(e, None)
      File "<string>", line 3, in raise_from
      File "/Users/john/.venvs/chaostk/lib/python3.7/site-packages/urllib3/connectionpool.py", line 416, in _make_request
        httplib_response = conn.getresponse()
      File "/usr/local/Cellar/python/3.7.5/Frameworks/Python.framework/Versions/3.7/lib/python3.7/http/client.py", line 1344, in getresponse
        response.begin()
      File "/usr/local/Cellar/python/3.7.5/Frameworks/Python.framework/Versions/3.7/lib/python3.7/http/client.py", line 306, in begin
        version, status, reason = self._read_status()
      File "/usr/local/Cellar/python/3.7.5/Frameworks/Python.framework/Versions/3.7/lib/python3.7/http/client.py", line 267, in _read_status
        line = str(self.fp.readline(_MAXLINE + 1), "iso-8859-1")
      File "/usr/local/Cellar/python/3.7.5/Frameworks/Python.framework/Versions/3.7/lib/python3.7/socket.py", line 589, in readinto
        return self._sock.recv_into(b)
    socket.timeout: timed out
    
    During handling of the above exception, another exception occurred:
    
    Traceback (most recent call last):
      File "/Users/john/.venvs/chaostk/lib/python3.7/site-packages/requests/adapters.py", line 449, in send
        timeout=timeout
      File "/Users/john/.venvs/chaostk/lib/python3.7/site-packages/urllib3/connectionpool.py", line 720, in urlopen
        method, url, error=e, _pool=self, _stacktrace=sys.exc_info()[2]
      File "/Users/john/.venvs/chaostk/lib/python3.7/site-packages/urllib3/util/retry.py", line 400, in increment
        raise six.reraise(type(error), error, _stacktrace)
      File "/Users/john/.venvs/chaostk/lib/python3.7/site-packages/urllib3/packages/six.py", line 735, in reraise
        raise value
      File "/Users/john/.venvs/chaostk/lib/python3.7/site-packages/urllib3/connectionpool.py", line 672, in urlopen
        chunked=chunked,
      File "/Users/john/.venvs/chaostk/lib/python3.7/site-packages/urllib3/connectionpool.py", line 423, in _make_request
        self._raise_timeout(err=e, url=url, timeout_value=read_timeout)
      File "/Users/john/.venvs/chaostk/lib/python3.7/site-packages/urllib3/connectionpool.py", line 331, in _raise_timeout
        self, url, "Read timed out. (read timeout=%s)" % timeout_value
    urllib3.exceptions.ReadTimeoutError: HTTPConnectionPool(host='localhost', port=8080): Read timed out. (read timeout=1)
    
    During handling of the above exception, another exception occurred:
    
    Traceback (most recent call last):
      File "/Users/john/.venvs/chaostk/lib/python3.7/site-packages/chaoslib/provider/http.py", line 53, in run_http_activity
        verify=verify_tls)
      File "/Users/john/.venvs/chaostk/lib/python3.7/site-packages/requests/sessions.py", line 546, in get
        return self.request('GET', url, **kwargs)
      File "/Users/john/.venvs/chaostk/lib/python3.7/site-packages/requests/sessions.py", line 533, in request
        resp = self.send(prep, **send_kwargs)
      File "/Users/john/.venvs/chaostk/lib/python3.7/site-packages/requests/sessions.py", line 646, in send
        r = adapter.send(request, **kwargs)
      File "/Users/john/.venvs/chaostk/lib/python3.7/site-packages/requests/adapters.py", line 529, in send
        raise ReadTimeout(e, request=request)
    requests.exceptions.ReadTimeout: HTTPConnectionPool(host='localhost', port=8080): Read timed out. (read timeout=1)
    
    During handling of the above exception, another exception occurred:
    
    Traceback (most recent call last):
      File "/Users/john/.venvs/chaostk/lib/python3.7/site-packages/chaoslib/activity.py", line 227, in run_activity
        result = run_http_activity(activity, configuration, secrets)
      File "/Users/john/.venvs/chaostk/lib/python3.7/site-packages/chaoslib/provider/http.py", line 89, in run_http_activity
        raise ActivityFailed("activity took too long to complete")
    chaoslib.exceptions.ActivityFailed: activity took too long to complete
[31m[2020-01-13 12:30:16 ERROR] [activity:184][39m   => failed: activity took too long to complete
[36m[2020-01-13 12:30:16 DEBUG] [__init__:355][39m No controls to apply on 'activity'
[33m[2020-01-13 12:30:16 WARNING] [hypothesis:201][39m Probe terminated unexpectedly, so its tolerance could not be validated
[36m[2020-01-13 12:30:16 DEBUG] [__init__:355][39m No controls to apply on 'hypothesis'
[2020-01-13 12:30:16 CRITICAL] [experiment:241] Steady state probe 'we-can-request-movie' is not in the given tolerance so failing this experiment
[32m[2020-01-13 12:30:16 INFO] [experiment:320][39m Let's rollback...
[36m[2020-01-13 12:30:16 DEBUG] [__init__:355][39m No controls to apply on 'rollback'
[32m[2020-01-13 12:30:16 INFO] [rollback:28][39m Rollback: disable_chaosmonkey
[36m[2020-01-13 12:30:16 DEBUG] [__init__:355][39m No controls to apply on 'activity'
[32m[2020-01-13 12:30:16 INFO] [activity:158][39m Action: disable_chaosmonkey
[36m[2020-01-13 12:30:16 DEBUG] [python:36][39m Activity 'disable_chaosmonkey' loaded from '/Users/john/.venvs/chaostk/lib/python3.7/site-packages/chaosspring/actions.py'
[36m[2020-01-13 12:30:16 DEBUG] [activity:176][39m   => succeeded with 'Chaos Monkey is disabled'
[36m[2020-01-13 12:30:16 DEBUG] [__init__:355][39m No controls to apply on 'activity'
[36m[2020-01-13 12:30:16 DEBUG] [__init__:355][39m No controls to apply on 'rollback'
[32m[2020-01-13 12:30:16 INFO] [experiment:270][39m Experiment ended with status: deviated
[32m[2020-01-13 12:30:16 INFO] [experiment:274][39m The steady-state has deviated, a weakness may have been discovered
[36m[2020-01-13 12:30:16 DEBUG] [__init__:355][39m No controls to apply on 'experiment'
[36m[2020-01-13 12:30:16 DEBUG] [__init__:72][39m Cleaning up controls
[36m[2020-01-13 12:30:16 DEBUG] [caching:42][39m Clearing activities cache
